Workbook

Sheet اسلحة
A1: الأقاليم | B1: عدد القضايا | C1: عدد الاقافات | D1: بندقية صيد | E1: مسدس | F1: بندقية ضغط هوائي | G1: خرطوشة | H1: اطلاقات | I1: ظروف | K1: عدد الاشعار
A2: نابل
A3: مدنين
A4: قفصة
A5: قبلي
A6: قابس
A7: صفاقس
A8: سيدي بوزيد | B8: 1 | D8: 1 | K8: 230
A9: سوسة
A10: سليانة | B10: 1 | C10: 1 | D10: 1 | G10: 22 | K10: 142/144
A11: زغوان
A12: جندوبة
A13: تونس
A14: توزر
A15: تطاوين
A16: بنزرت
A17: بن عروس
A18: باجة
A19: أريانة
A20: المهدية
A21: المنستير
A22: الكاف
... A31: إدارة الشؤون العدلية
A33: المجموع | B33: =SUM(B2:B31) -> 2 | C33: =SUM(C2:C31) -> 1 | D33: =SUM(D2:D31) -> 2 | E33: =SUM(E2:E31) -> 0 | F33: =SUM(F2:F31) -> 0 | G33: =SUM(G2:G31) -> 22 | H33: =SUM(H2:H31) -> 0 | I33: =SUM(I2:I31) -> 0 | K33: ***
M37: =IF(D33=0,"",IF(D33=1,"-عدد 01 بندقية صيد.",IF(AND(D33>=2,D33<=10),"- عدد "&D33&" بنادق صيد."," - عدد "&D33&" بندقية صيد."))) -> - عدد 2 بنادق صيد.
M38: =IF(E33=0,"",IF(E33=1,"-عدد 01 مسدس.",IF(AND(E33>=2,E33<=10),"- عدد "&E33&" مسدسات."," - عدد "&E33&" مسدس.")))
M39: =IF(F33=0,"",IF(F33=1,"-عدد 01 بندقية ضغط هوائي.",IF(AND(F33>=2,F33<=10),"- عدد "&F33&" بنادق ضغط هوائي."," - عدد "&F33&" بندقية ضغط هوائي.")))
M40: =IF(G33=0,"",IF(G33=1,"-عدد 01 خرطوشة.",IF(AND(G33>=2,G33<=10),"- عدد "&G33&" خراطيش."," - عدد "&G33&" خرطوشة."))) -> - عدد 22 خرطوشة.
M41: =IF(H33=0,"",IF(H33=1,"-عدد 01 اطلاقة.",IF(AND(H33>=2,H33<=10),"- عدد "&H33&" اطلاقات."," - عدد "&H33&" اطلاقة.")))
M42: =IF(I33=0,"",IF(I33=1,"-عدد 01 ظرف.",IF(AND(I33>=2,I33<=10),"- عدد "&I33&" ظروف."," - عدد "&I33&" ظرف.")))
M43: =IF(D39=0,"",IF(D39=1,"عدد 01 بندقية صيد."," عدد "&D39&" بنادق صيد."))
M45: =IF(M37<>"",M37&CHAR(10),"")&IF(M38<>"",M38&CHAR(10),"")&IF(M39<>"",M39&CHAR(10),"")&IF(M40<>"",M40&CHAR(10),"")&IF(M41<>"",M41&CHAR(10),"")&IF(M42<>"",M42,"") -> - عدد 2 بنادق صيد. - عدد 22 خرطوشة.

Sheet مشروبات كحولية
A1: الأقاليم | B1: عدد القضايا | C1: عدد الاقافات | D1: علب جعة. | E1: قوارير جعة. | F1: قوارير خمر | G1: قوارير مشربات كحولية فاخرة. | H1: قوارير كحولية. | I1: لتر من المشروبات المسكرة. | K1: عدد الاشعار
A2: نابل
A3: مدنين
A4: قفصة
A5: قبلي
A6: قابس
A7: صفاقس
A8: سيدي بوزيد
A9: سوسة
A10: سليانة
A11: زغوان
A12: جندوبة
A13: تونس
... A16: بنزرت
A17: بن عروس | B17: 1 | C17: 1 | D17: 2 | F17: 1 | K17: 407
A18: باجة
A19: أريانة
A20: المهدية
A21: المنستير
A22: الكاف
A23: القيروان | B23: 1 | C23: 1 | D23: 56 | F23: 2 | K23: 236
A24: القصرين
A25: الفرق المركزية للأبحاث
A26: إقليم الحرس البحري بالوسط
A27: إقليم الحرس البحري بالشمال
A28: إقليم الحرس البحري بالساحل
A29: إقليم الحرس البحري بالجنوب
A30: إدارة حرس المرور
A31: إدارة الشؤون العدلية
A33: المجموع | B33: =SUM(B2:B31) -> 2 | C33: =SUM(C2:C31) -> 2 | D33: =SUM(D2:D31) -> 58 | E33: =SUM(E2:E31) -> 0 | F33: =SUM(F2:F31) -> 3 | G33: =SUM(G2:G31) -> 0 | H33: =SUM(H2:H31) -> 0 | I33: =SUM(I2:I31) -> 0 | K33: ***
M37: =IF(D33=0,"",IF(D33=1,"-عدد 01 علبة جعة .",IF(AND(D33>=2,D33<=10),"- عدد "&D33&" علب جعة ."," - عدد "&D33&" علبة جعة."))) -> - عدد 58 علبة جعة.
M38: =IF(E33=0,"",IF(E33=1,"-عدد 01 قارورة جعة .",IF(AND(E33>=2,E33<=10),"- عدد "&E33&" قواريير جعة ."," - عدد "&E33&" قارورة جعة.")))
M39: =IF(F33=0,"",IF(F33=1,"-عدد 01 قارورة خمر .",IF(AND(F33>=2,F33<=10),"- عدد "&F33&" قوارير خمر ."," - عدد "&F33&" قارورة خمر."))) -> - عدد 3 قوارير خمر .
M40: =IF(G33=0,"",IF(G33=1,"-عدد 01 قارورة مشروبات كحولية فاخرة .",IF(AND(G33>=2,G33<=10),"- عدد "&G33&" قوارير مشروبات كحولية فاخرة ."," - عدد "&G33&" قارورة مشروبات كحولية فاخرة.")))
M41: =IF(H33=0,"",IF(H33=1,"-عدد 01 قارورة كحول .",IF(AND(H33>=2,H33<=10),"- عدد "&H33&" قوارير كحول ."," - عدد "&H33&" قارورة كحول.")))
M42: =IF(I33=0,"",IF(I33=1,"- عدد 01 لتر من المشروبات المسكرة . ","-عدد "&I33&" لتر من المشروبات المسكرة ."))
M43: =IF(D39=0,"",IF(D39=1,"- عدد 01 علبة جعة ","-عدد "&D39&" علب جعة."))
M45: =IF(M37<>"",M37&CHAR(10),"")&IF(M38<>"",M38&CHAR(10),"")&IF(M39<>"",M39&CHAR(10),"")&IF(M40<>"",M40&CHAR(10),"")&IF(M41<>"",M41&CHAR(10),"")&IF(M42<>"",M42,"") -> - عدد 58 علبة جعة.- عدد 3 قوارير خمر .

Sheet مخدرات
D1: نوع القضية | H1: الموقوفين | L1: قنب هندي | Q1: أقراص مخدرة | S1: كوكايين | V1: هيروين | Y1: ماريخوانا | AB1: مختلفة | AC1: اورق لف | AE1: المحجوز
A2: الأقاليم | B2: مكان الضبط | C2: عدد القضايا | D2: استهلاك مخدرات | E2: مسك مخدرات بغاية الترويج | F2: تهريب المخدرات | G2: ترويج مواد سمية | H2: استهلاك مخدرات2 | I2: مسك مخدرات بغاية الترويج3 | J2: تهريب المخدرات4 | K2: ترويج مواد سمية2 | L2: سيجارة محشوة | M2: غرام قنب هندي | N2: قطعة | O2: صفيحة قنب هندي | P2: كبسولة | Q2: قرص | R2: صفيحة أقراص | S2: غرام كوكايين | T2: لفافة | U2: كمية | V2: غرام هيروين | W2: حقنة | X2: هيروين مختلفة | Y2: غرام ماريخوانا | Z2: حبة | AA2: نبتة | AB2: مختلفة | AC2: ورقة | AD2: علبة | AE2: سيارة | AF2: شاحنة | AG2: دراجة نارية | AH2: هاتف جوال | AI2: الة حادة | AJ2: غاز مشل للحركة | AK2: صحن | AL2: ميزان | AM2: بطاقة بنكية | AN2: بطاقة تعرف وطنية | AO2: علب جعة | AP2: بندقية صيد | AQ2: د.التونسي | AR2: الدولار | AS2: الأورو | AT2: محجوزات أخرى | AV2: عدد الاشعار
A3: نابل
A4: مدنين
A5: قفصة
A6: قبلي
A7: قابس
A8: صفاقس
A9: سيدي بوزيد
A10: سوسة
A11: سليانة
A12: زغوان
A13: جندوبة
A14: تونس | B14: حي الشباب | C14: 1 | E14: 1 | I14: 1 | AL14: 1 | AQ14: 84 | AV14: 288
A15: توزر
A16: تطاوين
A17: بنزرت
A18: بن عروس
A19: باجة
A20: المهدية
A21: المنستير | B21: منزل النور | C21: 1 | D21: 1 | H21: 2 | AK21: 1 | AV21: 181
A22: الكاف
A23: القيروان
A24: القصرين
A25: الفرق المركزية للأبحاث | B25: العوينة | C25: 1 | E25: 1 | I25: 1 | N25: 1 | Q25: 22 | AH25: 1 | AV25: 4
A26: إقليم الحرس البحري بالوسط
A27: إقليم الحرس البحري بالشمال
A28: إقليم الحرس البحري بالساحل
A29: إقليم الحرس البحري بالجنوب
A30: أريانة
A31: إدارة حرس المرور
A32: إدارة الشؤون العدلية
A34: المجموع | B34: =SUM(Tableau6[مكان الضبط]) -> 0 | C34: =SUM(Tableau6[عدد القضايا]) -> 3 | D34: =SUM(Tableau6[استهلاك مخدرات]) -> 1 | E34: =SUM(Tableau6[مسك مخدرات بغاية الترويج]) -> 2 | F34: =SUM(Tableau6[تهريب المخدرات]) -> 0 | G34: =SUM(Tableau6[ترويج مواد سمية]) -> 0 | H34: =SUM(Tableau6[استهلاك مخدرات2]) -> 2 | I34: =SUM(Tableau6[مسك مخدرات بغاية الترويج3]) -> 2 | J34: =SUM(Tableau6[تهريب المخدرات4]) -> 0 | K34: =SUM(Tableau6[ترويج مواد سمية2]) -> 0 | L34: =SUM(Tableau6[سيجارة محشوة]) -> 0 | M34: =SUM(Tableau6[غرام قنب هندي]) -> 0 | N34: =SUM(Tableau6[قطعة]) -> 1 | O34: =SUM(Tableau6[صفيحة قنب هندي]) -> 0 | P34: =SUM(Tableau6[كبسولة]) -> 0 | Q34: =SUM(Tableau6[قرص]) -> 22 | R34: =SUM(Tableau6[صفيحة أقراص]) -> 0 | S34: =SUM(Tableau6[غرام كوكايين]) -> 0 | T34: =SUM(Tableau6[لفافة]) -> 0 | U34: =U3&U4&U5&U6&U7&U8&U9&U10&U11&U12&U13&U14&U15&U16&U17&U18&U19&U20&U21&U22&U23&U24&U25&U26&U27&U28&U29&U30&U31&U32 | V34: =SUM(Tableau6[غرام هيروين]) -> 0 | W34: =SUM(Tableau6[حقنة]) -> 0 | X34: =X3&X4&X5&X6&X7&X8&X9&X10&X11&X12&X13&X14&X15&X16&X17&X18&X19&X20&X21&X22&X23&X24&X25&X26&X27&X28&X29&X30&X31&X32 | Y34: =SUM(Tableau6[غرام ماريخوانا]) -> 0 | Z34: =SUM(Tableau6[حبة]) -> 0 | AA34: =SUM(Tableau6[نبتة]) -> 0 | AB34: =AB3&AB4&AB5&AB6&AB7&AB8&AB9&AB10&AB11&AB12&AB13&AB14&AB15&AB16&AB17&AB18&AB19&AB20&AB21&AB22&AB23&AB24&AB25&AB26&AB27&AB28&AB29&AB30&AB31&AB32 | AC34: =SUM(Tableau6[ورقة]) -> 0 | AD34: =SUM(Tableau6[علبة]) -> 0 | AE34: =SUM(Tableau6[سيارة]) -> 0 | AF34: =SUM(Tableau6[شاحنة]) -> 0 | AG34: =SUM(Tableau6[دراجة نارية]) -> 0 | AH34: =SUM(Tableau6[هاتف جوال]) -> 1 | AI34: =SUM(Tableau6[الة حادة]) -> 0 | AJ34: =SUM(Tableau6[غاز مشل للحركة]) -> 0 | AK34: =SUM(Tableau6[صحن]) -> 1 | AL34: =SUM(Tableau6[ميزان]) -> 1 | AM34: =SUM(Tableau6[بطاقة بنكية]) -> 0 | AN34: =SUM(Tableau6[بطاقة تعرف وطنية]) -> 0 | AO34: =SUM(Tableau6[علب جعة]) -> 0 | AP34: =SUM(Tableau6[بندقية صيد]) -> 0 | AQ34: =SUM(Tableau6[د.التونسي]) -> 84 | AR34: =SUM(Tableau6[الدولار]) -> 0 | AS34: =SUM(Tableau6[الأورو]) -> 0
H40: قنب هندي | N40: أقراص مخدرة | S40: كوكايين | X40: هيروين | AC40: ماريخوانة | AG40: مختلفة
H41: =IF(L34=0,"",IF(L34=1,"-عدد 01 سيجارة محشوة بمخدر القنب الهندي .",IF(AND(L34>=2,L34<=10),"- عدد "&L34&" سجائر محشوة بمخدر القنب الهندي ."," - عدد "&L34&" سيجارة محشوة بمخدر القنب الهندي."))) | N41: =IF(Q34=0,"",IF(Q34=1,"-عدد 01 قرص مخدر .",IF(AND(Q34>=2,Q34<=10),"- عدد "&Q34&" أقراص مخدرة ."," - عدد "&Q34&" قرص مخدر."))) -> - عدد 22 قرص مخدر. | S41: =IF(S34=0,""," - حوالي "&S34&" غرام من مخدر الكوكايين.") | X41: =IF(V34=0,""," - حوالي "&V34&" غرام من مخدر الهيروين.") | AC41: =IF(Y34=0,""," - حوالي "&Y34&" غرام من مخدر الماريخوانا.") | AG41: =IF(OR(AB34=0,AB34=""),""," - "&AB34&".")
H42: =IF(N34=0,"",IF(N34=1,"-عدد 01 قطعة من مخدر القنب الهندي .",IF(AND(N34>=2,N34<=10),"- عدد "&N34&" قطع من مخدر القنب الهندي ."," - عدد "&N34&" قطعة من مخدر القنب الهندي."))) -> -عدد 01 قطعة من مخدر القنب الهندي . | N42: =IF(R34=0,"",IF(R34=1,"-عدد 01 صفيحة أقراص مخدر .",IF(AND(R34>=2,R34<=10),"- عدد "&R34&" صفائح أقراص مخدرة ."," - عدد "&R34&" صفيحة أقراص مخدر."))) | S42: =IF(T34=0,"",IF(T34=1,"-عدد 01 لفافة من مخدر الكوكايين .",IF(AND(T34>=2,T34<=10),"- عدد "&T34&" لفافات من مخدر الكوكايين ."," - عدد "&T34&" لفافة من مخدر الكوكايين."))) | X42: =IF(W34=0,"",IF(W34=1,"-عدد 01 حقنة من مخدر الهيروين .",IF(AND(W34>=2,W34<=10),"- عدد "&W34&" حقنات من مخدر الهيروين ."," - عدد "&W34&" حقنة من مخدر الهيروين."))) | AC42: =IF(Z34=0,"",IF(Z34=1,"-عدد 01 حبة من مخدر الماريخوانا .",IF(AND(Z34>=2,Z34<=10),"- عدد "&Z34&" حبات من مخدر الماريخوانا ."," - عدد "&Z34&" حبة من مخدر الماريخوانا.")))
H43: =IF(O34=0,"",IF(O34=1,"-عدد 01 صفيحة من مخدر القنب الهندي .",IF(AND(O34>=2,O34<=10),"- عدد "&O34&" صفائح من مخدر القنب الهندي ."," - عدد "&O34&" صفيحة من مخدر القنب الهندي."))) | S43: =IF(OR(U34=0,U34=""),""," - "&U34&" من مخدر الكوكايين.") | X43: =IF(OR(X34=0,X34=""),""," - "&X34&" من مخدر الهيروين.") | AC43: =IF(AA34=0,"",IF(AA34=1,"-عدد 01 نبتة مخدر الماريخوانا .",IF(AND(AA34>=2,AA34<=10),"- عدد "&AA34&" نبتات مخدر الماريخوانا ."," - عدد "&AA34&" نبتة مخدر الماريخوانا.")))
H44: =IF(P34=0,"",IF(P34=1,"-عدد 01 كبسولة من مخدر القنب الهندي .",IF(AND(P34>=2,P34<=10),"- عدد "&P34&" كبسولات من مخدر القنب الهندي ."," - عدد "&P34&" كبسولة من مخدر القنب الهندي.")))
H45: =IF(M34=0,""," - حوالي "&M34&" غرام من مخدر القنب الهندي.")
I48: =IF(H41<>"",H41&CHAR(10),"")&IF(H42<>"",H42&CHAR(10),"")&IF(H45<>"",H45&CHAR(10),"")&IF(H43<>"",H43&CHAR(10),"")&IF(H44<>"",H44&CHAR(10),"")&IF(N41<>"",N41&CHAR(10),"")&IF(N42<>"",N42&CHAR(10),"")&IF(S41<>"",S41&CHAR(10),"")&IF(S42<>"",S42&CHAR(10),"")&IF(S43<>"",S43&CHAR(10),"")&IF(X41<>"",X41&CHAR(10),"")&IF(X42<>"",X42&CHAR(10),"")&IF(X43<>"",X43&CHAR(10),"")&IF(AC41<>"",AC41&CHAR(10),"")&IF(AC42<>"",AC42&CHAR(10),"")&IF(AG41<>"",AG41&CHAR(10),"")&IF(AC43<>"",AC43&CHAR(10),"") -> -عدد 01 قطعة من مخدر القنب الهندي . - عدد 22 قرص مخدر.

Sheet مخدرات (2)
A1: وزارة الداخليـــــــة
A2: الإدارة العامة للحرس الوطني | D2: كشف يومي في قضايـا المخدرات والموقوفين ليوم 2026/01/11
A3: إدارة عمليات الحرس الوطني
A4: عــــد / 3933 /د
A5: الأقاليم | B5: مكان الضبط | C5: عدد القضايا | D5: نوع القضية | H5: الموقوفين | Q5: الأطراف الأمنية المورطة | R5: الضبطيات
L6: قنب هندي | R6: قنب هندي | S6: أقراص مخدرة | U6: أقراص مخدرة | V6: كوكايين (غرام) | Y6: كوكايين | Z6: هيروين | AC6: هيروين | AD6: ماريخوانا | AG6: ماريخوانا | AH6: مختلفة | AI6: اورق لف | AL6: المحجوز | BB6: المحجوز (المبالغ المالية ,الوسائل..)
D7: استهلاك مخدرات | E7: مسك مخدرات بغاية الترويج | F7: تهريب المخدرات | G7: ترويج مواد سمية | H7: استهلاك مخدرات | I7: مسك مخدرات بغاية الترويج | J7: تهريب المخدرات | K7: ترويج مواد سمية | L7: سيجارة محشوة | M7: غرام | N7: قطع | O7: صفيحة | P7: كبسولة | S7: قرص | T7: صفيحة | V7: غرام | W7: لفافة | X7: كمية | Z7: غرام | AA7: حقنة | AB7: أخرى | AD7: غرام | AE7: حبات | AF7: نبتة | AH7: مختلفة | AI7: أوراق لف | AJ7: علبة أوراق لف | AL7: سيارة | AM7: شاحنة | AN7: دراجة نارية | AO7: هاتف جوال | AP7: الة حادة | AQ7: غاز مشل للحركة | AR7: صحن | AS7: ميزان | AT7: بطاقة بنكية | AU7: بطاقة تعرف وطنية | AV7: علب جعة | AW7: بندقية صيد | AX7: د.التونسي | AY7: الدولار | AZ7: الأورو | BA7: مختلفة2
B8: =IF(ISBLANK($A8),"",IF(ISBLANK(VLOOKUP($A8,Tableau6[],2,FALSE)),"",VLOOKUP($A8,Tableau6[],2,FALSE))) | C8: =IF(ISBLANK($A8),"",IF(ISBLANK(VLOOKUP($A8,Tableau6[],3,FALSE)),"",VLOOKUP($A8,Tableau6[],3,FALSE))) | D8: =IF(ISBLANK($A8),"",IF(ISBLANK(VLOOKUP($A8,Tableau6[],4,FALSE)),"",VLOOKUP($A8,Tableau6[],4,FALSE))) | E8: =IF(ISBLANK($A8),"",IF(ISBLANK(VLOOKUP($A8,Tableau6[],5,FALSE)),"",VLOOKUP($A8,Tableau6[],5,FALSE))) | F8: =IF(ISBLANK($A8),"",IF(ISBLANK(VLOOKUP($A8,Tableau6[],6,FALSE)),"",VLOOKUP($A8,Tableau6[],6,FALSE))) | G8: =IF(ISBLANK($A8),"",IF(ISBLANK(VLOOKUP($A8,Tableau6[],7,FALSE)),"",VLOOKUP($A8,Tableau6[],7,FALSE))) | H8: =IF(ISBLANK($A8),"",IF(ISBLANK(VLOOKUP($A8,Tableau6[],8,FALSE)),"",VLOOKUP($A8,Tableau6[],8,FALSE))) | I8: =IF(ISBLANK($A8),"",IF(ISBLANK(VLOOKUP($A8,Tableau6[],9,FALSE)),"",VLOOKUP($A8,Tableau6[],9,FALSE))) | J8: =IF(ISBLANK($A8),"",IF(ISBLANK(VLOOKUP($A8,Tableau6[],10,FALSE)),"",VLOOKUP($A8,Tableau6[],10,FALSE))) | K8: =IF(ISBLANK($A8),"",IF(ISBLANK(VLOOKUP($A8,Tableau6[],11,FALSE)),"",VLOOKUP($A8,Tableau6[],11,FALSE))) | L8: =IF(ISBLANK($A8),"",IF(ISBLANK(VLOOKUP($A8,Tableau6[],12,FALSE)),"",VLOOKUP($A8,Tableau6[],12,FALSE))) | M8: =IF(ISBLANK($A8),"",IF(ISBLANK(VLOOKUP($A8,Tableau6[],13,FALSE)),"",VLOOKUP($A8,Tableau6[],13,FALSE))) | N8: =IF(ISBLANK($A8),"",IF(ISBLANK(VLOOKUP($A8,Tableau6[],14,FALSE)),"",VLOOKUP($A8,Tableau6[],14,FALSE))) | O8: =IF(ISBLANK($A8),"",IF(ISBLANK(VLOOKUP($A8,Tableau6[],15,FALSE)),"",VLOOKUP($A8,Tableau6[],15,FALSE))) | P8: =IF(ISBLANK($A8),"",IF(ISBLANK(VLOOKUP($A8,Tableau6[],16,FALSE)),"",VLOOKUP($A8,Tableau6[],16,FALSE))) | R8: =IF(AND(OR(L8="",L8=0),OR(M8="",M8=0),OR(N8="",N8=0),OR(O8="",O8=0)*OR(P8="",P8=0)),"",TRIM(LEFT(IF(AND(L8<>"",L8>0),L8&" "&$L$7&" / ","")&IF(AND(M8<>"",M8>0),M8&" "&$M$7&" / ","")&IF(AND(N8<>"",N8>0),N8&" "&$N$7&" / ","")&IF(AND(O8<>"",O8>0),O8&" "&$O$7&" / ","")&IF(AND(P8<>"",P8>0),P8&" "&$P$7&" / ",""),LEN(IF(AND(L8<>"",L8>0),L8&" "&$L$7&" / ","")&IF(AND(M8<>"",M8>0),M8&" "&$M$7&" / ","")&IF(AND(N8<>"",N8>0),N8&" "&$N$7&" / ","")&IF(AND(O8<>"",O8>0),O8&" "&$O$7&" / ","")&IF(AND(P8<>"",P8>0),P8&" "&$P$7&" / ",""))-2))) | S8: =IF(ISBLANK($A8),"",IF(ISBLANK(VLOOKUP($A8,Tableau6[],17,FALSE)),"",VLOOKUP($A8,Tableau6[],17,FALSE))) | T8: =IF(ISBLANK($A8),"",IF(ISBLANK(VLOOKUP($A8,Tableau6[],18,FALSE)),"",VLOOKUP($A8,Tableau6[],18,FALSE))) | U8: =IF(AND(OR(S8="",S8=0),OR(T8="",T8=0)),"",TRIM(LEFT(IF(AND(S8<>"",S8>0),S8&" "&$S$7&" / ","")&IF(AND(T8<>"",T8>0),T8&" "&$T$7&" / ",""),LEN(IF(AND(S8<>"",S8>0),S8&" "&$S$7&" / ","")&IF(AND(T8<>"",T8>0),T8&" "&$T$7&" / ",""))-2))) | V8: =IF(ISBLANK($A8),"",IF(ISBLANK(VLOOKUP($A8,Tableau6[],19,FALSE)),"",VLOOKUP($A8,Tableau6[],19,FALSE))) | W8: =IF(ISBLANK($A8),"",IF(ISBLANK(VLOOKUP($A8,Tableau6[],20,FALSE)),"",VLOOKUP($A8,Tableau6[],20,FALSE))) | X8: =IF(ISBLANK($A8),"",IF(ISBLANK(VLOOKUP($A8,Tableau6[],21,FALSE)),"",VLOOKUP($A8,Tableau6[],21,FALSE))) | Y8: =IF(AND(OR(V8="",V8=0),OR(W8="",W8=0),OR(X8="",X8=0)),"",TRIM(LEFT(IF(AND(V8<>"",V8>0),V8&" "&$V$7&" / ","")&IF(AND(W8<>"",W8>0),W8&" "&$W$7&" / ","")&IF(AND(X8<>"",X8>0),X8&" "&" / ",""),LEN(IF(AND(V8<>"",V8>0),V8&" "&$V$7&" / ","")&IF(AND(W8<>"",W8>0),W8&" "&$W$7&" / ","")&IF(AND(X8<>"",X8>0),X8&" "&" / ",""))-2))) | Z8: =IF(ISBLANK($A8),"",IF(ISBLANK(VLOOKUP($A8,Tableau6[],22,FALSE)),"",VLOOKUP($A8,Tableau6[],22,FALSE))) | AA8: =IF(ISBLANK($A8),"",IF(ISBLANK(VLOOKUP($A8,Tableau6[],23,FALSE)),"",VLOOKUP($A8,Tableau6[],23,FALSE))) | AB8: =IF(ISBLANK($A8),"",IF(ISBLANK(VLOOKUP($A8,Tableau6[],24,FALSE)),"",VLOOKUP($A8,Tableau6[],24,FALSE))) | AC8: =IF(AND(OR(Z8="",Z8=0),OR(AA8="",AA8=0),OR(AB8="",AB8=0)),"",TRIM(LEFT(IF(AND(Z8<>"",Z8>0),Z8&" "&$Z$7&" / ","")&IF(AND(AA8<>"",AA8>0),AA8&" "&$AA$7&" / ","")&IF(AND(AB8<>"",AB8>0),AB8&" "&" / ",""),LEN(IF(AND(Z8<>"",Z8>0),Z8&" "&$Z$7&" / ","")&IF(AND(AA8<>"",AA8>0),AA8&" "&$AA$7&" / ","")&IF(AND(AB8<>"",AB8>0),AB8&" "&" / ",""))-2))) | AD8: =IF(ISBLANK($A8),"",IF(ISBLANK(VLOOKUP($A8,Tableau6[],25,FALSE)),"",VLOOKUP($A8,Tableau6[],25,FALSE))) | AE8: =IF(ISBLANK($A8),"",IF(ISBLANK(VLOOKUP($A8,Tableau6[],26,FALSE)),"",VLOOKUP($A8,Tableau6[],26,FALSE))) | AF8: =IF(ISBLANK($A8),"",IF(ISBLANK(VLOOKUP($A8,Tableau6[],27,FALSE)),"",VLOOKUP($A8,Tableau6[],27,FALSE))) | AG8: =IF(AND(OR(AD8="",AD8=0),OR(AE8="",AE8=0),OR(AF8="",AF8=0)),"",TRIM(LEFT(IF(AND(AD8<>"",AD8>0),AD8&" "&$AD$7&" / ","")&IF(AND(AE8<>"",AE8>0),AE8&" "&$AE$7&" / ","")&IF(AND(AF8<>"",AF8>0),AF8&" "&$AF$7&" / ",""),LEN(IF(AND(AD8<>"",AD8>0),AD8&" "&$AD$7&" / ","")&IF(AND(AE8<>"",AE8>0),AE8&" "&$AE$7&" / ","")&IF(AND(AF8<>"",AF8>0),AF8&" "&$AF$7&" / ",""))-2))) | AH8: =IF(ISBLANK($A8),"",IF(ISBLANK(VLOOKUP($A8,Tableau6[],28,FALSE)),"",VLOOKUP($A8,Tableau6[],28,FALSE))) | AI8: =IF(ISBLANK($A8),"",IF(ISBLANK(VLOOKUP($A8,Tableau6[],29,FALSE)),"",VLOOKUP($A8,Tableau6[],29,FALSE))) | AJ8: =IF(ISBLANK($A8),"",IF(ISBLANK(VLOOKUP($A8,Tableau6[],30,FALSE)),"",VLOOKUP($A8,Tableau6[],30,FALSE))) | AK8: =IF(AND(OR(AI8="",AI8=0),OR(AJ8="",AJ8=0)),"",TRIM(LEFT(IF(AND(AI8<>"",AI8>0),AI8&" "&$AI$7&" / ","")&IF(AND(AJ8<>"",AJ8>0),AJ8&" "&$AJ$7&" / ",""),LEN(IF(AND(AI8<>"",AI8>0),AI8&" "&$AI$7&" / ","")&IF(AND(AJ8<>"",AJ8>0),AJ8&" "&$AJ$7&" / ",""))-2))) | AL8: =IF(ISBLANK($A8),"",IF(ISBLANK(VLOOKUP($A8,Tableau6[],31,FALSE)),"",VLOOKUP($A8,Tableau6[],31,FALSE))) | AM8: =IF(ISBLANK($A8),"",IF(ISBLANK(VLOOKUP($A8,Tableau6[],32,FALSE)),"",VLOOKUP($A8,Tableau6[],32,FALSE))) | AN8: =IF(ISBLANK($A8),"",IF(ISBLANK(VLOOKUP($A8,Tableau6[],33,FALSE)),"",VLOOKUP($A8,Tableau6[],33,FALSE))) | AO8: =IF(ISBLANK($A8),"",IF(ISBLANK(VLOOKUP($A8,Tableau6[],34,FALSE)),"",VLOOKUP($A8,Tableau6[],34,FALSE))) | AP8: =IF(ISBLANK($A8),"",IF(ISBLANK(VLOOKUP($A8,Tableau6[],35,FALSE)),"",VLOOKUP($A8,Tableau6[],35,FALSE))) | AQ8: =IF(ISBLANK($A8),"",IF(ISBLANK(VLOOKUP($A8,Tableau6[],36,FALSE)),"",VLOOKUP($A8,Tableau6[],36,FALSE))) | AR8: =IF(ISBLANK($A8),"",IF(ISBLANK(VLOOKUP($A8,Tableau6[],37,FALSE)),"",VLOOKUP($A8,Tableau6[],37,FALSE))) | AS8: =IF(ISBLANK($A8),"",IF(ISBLANK(VLOOKUP($A8,Tableau6[],38,FALSE)),"",VLOOKUP($A8,Tableau6[],38,FALSE))) | AT8: =IF(ISBLANK($A8),"",IF(ISBLANK(VLOOKUP($A8,Tableau6[],39,FALSE)),"",VLOOKUP($A8,Tableau6[],39,FALSE))) | AU8: =IF(ISBLANK($A8),"",IF(ISBLANK(VLOOKUP($A8,Tableau6[],40,FALSE)),"",VLOOKUP($A8,Tableau6[],40,FALSE))) | AV8: =IF(ISBLANK($A8),"",IF(ISBLANK(VLOOKUP($A8,Tableau6[],41,FALSE)),"",VLOOKUP($A8,Tableau6[],41,FALSE))) | AW8: =IF(ISBLANK($A8),"",IF(ISBLANK(VLOOKUP($A8,Tableau6[],42,FALSE)),"",VLOOKUP($A8,Tableau6[],42,FALSE))) | AX8: =IF(ISBLANK($A8),"",IF(ISBLANK(VLOOKUP($A8,Tableau6[],43,FALSE)),"",VLOOKUP($A8,Tableau6[],43,FALSE))) | AY8: =IF(ISBLANK($A8),"",IF(ISBLANK(VLOOKUP($A8,Tableau6[],44,FALSE)),"",VLOOKUP($A8,Tableau6[],44,FALSE))) | AZ8: =IF(ISBLANK($A8),"",IF(ISBLANK(VLOOKUP($A8,Tableau6[],45,FALSE)),"",VLOOKUP($A8,Tableau6[],45,FALSE))) | BA8: =IF(ISBLANK($A8),"",IF(ISBLANK(VLOOKUP($A8,Tableau6[],46,FALSE)),"",VLOOKUP($A8,Tableau6[],46,FALSE))) | BB8: =IF(AND(OR(AK8="",AK8=0),OR(AL8="",AL8=0),OR(AM8="",AM8=0),OR(AN8="",AN8=0),OR(AO8="",AO8=0),OR(AP8="",AP8=0),OR(AQ8="",AQ8=0),OR(AR8="",AR8=0),OR(AS8="",AS8=0),OR(AT8="",AT8=0),OR(AU8="",AU8=0),OR(AV8="",AV8=0),OR(AW8="",AW8=0),OR(AX8="",AX8=0),OR(AY8="",AY8=0),OR(AZ8="",AZ8=0),OR(BA8="",BA8=0)),"",TRIM(LEFT(IF(AND(AK8<>"",AK8>0),AK8&" "&$AK$7&" / ","")&IF(AND(AL8<>"",AL8>0),AL8&" "&$AL$7&" / ","")&IF(AND(AM8<>"",AM8>0),AM8&" "&$AM$7&" / ","")&IF(AND(AN8<>"",AN8>0),AN8&" "&$AN$7&" / ","")&IF(AND(AO8<>"",AO8>0),AO8&" "&$AO$7&" / ","")&IF(AND(AP8<>"",AP8>0),AP8&" "&$AP$7&" / ","")&IF(AND(AQ8<>"",AQ8>0),AQ8&" "&$AQ$7&" / ","")&IF(AND(AR8<>"",AR8>0),AR8&" "&$AR$7&" / ","")&IF(AND(AS8<>"",AS8>0),AS8&" "&$AS$7&" / ","")&IF(AND(AT8<>"",AT8>0),AT8&" "&$AT$7&" / ","")&IF(AND(AU8<>"",AU8>0),AU8&" "&$AU$7&" / ","")&IF(AND(AV8<>"",AV8>0),AV8&" "&$AV$7&" / ","")&IF(AND(AW8<>"",AW8>0),AW8&" "&$AW$7&" / ","")&IF(AND(AX8<>"",AX8>0),AX8&" "&$AX$7&" / ","")&IF(AND(AY8<>"",AY8>0),AY8&" "&$AY$7&" / ","")&IF(AND(AZ8<>"",AZ8>0),AZ8&" "&$AZ$7&" / ","")&IF(AND(BA8<>"",BA8>0),BA8&" "&" / ",""),LEN(IF(AND(AK8<>"",AK8>0),AK8&" "&$AK$7&" / ","")&IF(AND(AL8<>"",AL8>0),AL8&" "&$AL$7&" / ","")&IF(AND(AM8<>"",AM8>0),AM8&" "&$AM$7&" / ","")&IF(AND(AN8<>"",AN8>0),AN8&" "&$AN$7&" / ","")&IF(AND(AO8<>"",AO8>0),AO8&" "&$AO$7&" / ","")&IF(AND(AP8<>"",AP8>0),AP8&" "&$AP$7&" / ","")&IF(AND(AQ8<>"",AQ8>0),AQ8&" "&$AQ$7&" / ","")&IF(AND(AR8<>"",AR8>0),AR8&" "&$AR$7&" / ","")&IF(AND(AS8<>"",AS8>0),AS8&" "&$AS$7&" / ","")&IF(AND(AT8<>"",AT8>0),AT8&" "&$AT$7&" / ","")&IF(AND(AU8<>"",AU8>0),AU8&" "&$AU$7&" / ","")&IF(AND(AV8<>"",AV8>0),AV8&" "&$AV$7&" / ","")&IF(AND(AW8<>"",AW8>0),AW8&" "&$AW$7&" / ","")&IF(AND(AX8<>"",AX8>0),AX8&" "&$AX$7&" / ","")&IF(AND(AY8<>"",AY8>0),AY8&" "&$AY$7&" / ","")&IF(AND(AZ8<>"",AZ8>0),AZ8&" "&$AZ$7&" / ","")&IF(AND(BA8<>"",BA8>0),BA8&" "" / ",""))-2)))
A9: تونس | B9: =IF(ISBLANK($A9),"",IF(ISBLANK(VLOOKUP($A9,Tableau6[],2,FALSE)),"",VLOOKUP($A9,Tableau6[],2,FALSE))) -> حي الشباب | C9: =IF(ISBLANK($A9),"",IF(ISBLANK(VLOOKUP($A9,Tableau6[],3,FALSE)),"",VLOOKUP($A9,Tableau6[],3,FALSE))) -> 1 | D9: =IF(ISBLANK($A9),"",IF(ISBLANK(VLOOKUP($A9,Tableau6[],4,FALSE)),"",VLOOKUP($A9,Tableau6[],4,FALSE))) | E9: =IF(ISBLANK($A9),"",IF(ISBLANK(VLOOKUP($A9,Tableau6[],5,FALSE)),"",VLOOKUP($A9,Tableau6[],5,FALSE))) -> 1 | F9: =IF(ISBLANK($A9),"",IF(ISBLANK(VLOOKUP($A9,Tableau6[],6,FALSE)),"",VLOOKUP($A9,Tableau6[],6,FALSE))) | G9: =IF(ISBLANK($A9),"",IF(ISBLANK(VLOOKUP($A9,Tableau6[],7,FALSE)),"",VLOOKUP($A9,Tableau6[],7,FALSE))) | H9: =IF(ISBLANK($A9),"",IF(ISBLANK(VLOOKUP($A9,Tableau6[],8,FALSE)),"",VLOOKUP($A9,Tableau6[],8,FALSE))) | I9: =IF(ISBLANK($A9),"",IF(ISBLANK(VLOOKUP($A9,Tableau6[],9,FALSE)),"",VLOOKUP($A9,Tableau6[],9,FALSE))) -> 1 | J9: =IF(ISBLANK($A9),"",IF(ISBLANK(VLOOKUP($A9,Tableau6[],10,FALSE)),"",VLOOKUP($A9,Tableau6[],10,FALSE))) | K9: =IF(ISBLANK($A9),"",IF(ISBLANK(VLOOKUP($A9,Tableau6[],11,FALSE)),"",VLOOKUP($A9,Tableau6[],11,FALSE))) | L9: =IF(ISBLANK($A9),"",IF(ISBLANK(VLOOKUP($A9,Tableau6[],12,FALSE)),"",VLOOKUP($A9,Tableau6[],12,FALSE))) | M9: =IF(ISBLANK($A9),"",IF(ISBLANK(VLOOKUP($A9,Tableau6[],13,FALSE)),"",VLOOKUP($A9,Tableau6[],13,FALSE))) | N9: =IF(ISBLANK($A9),"",IF(ISBLANK(VLOOKUP($A9,Tableau6[],14,FALSE)),"",VLOOKUP($A9,Tableau6[],14,FALSE))) | O9: =IF(ISBLANK($A9),"",IF(ISBLANK(VLOOKUP($A9,Tableau6[],15,FALSE)),"",VLOOKUP($A9,Tableau6[],15,FALSE))) | P9: =IF(ISBLANK($A9),"",IF(ISBLANK(VLOOKUP($A9,Tableau6[],16,FALSE)),"",VLOOKUP($A9,Tableau6[],16,FALSE))) | R9: =IF(AND(OR(L9="",L9=0),OR(M9="",M9=0),OR(N9="",N9=0),OR(O9="",O9=0)*OR(P9="",P9=0)),"",TRIM(LEFT(IF(AND(L9<>"",L9>0),L9&" "&$L$7&" / ","")&IF(AND(M9<>"",M9>0),M9&" "&$M$7&" / ","")&IF(AND(N9<>"",N9>0),N9&" "&$N$7&" / ","")&IF(AND(O9<>"",O9>0),O9&" "&$O$7&" / ","")&IF(AND(P9<>"",P9>0),P9&" "&$P$7&" / ",""),LEN(IF(AND(L9<>"",L9>0),L9&" "&$L$7&" / ","")&IF(AND(M9<>"",M9>0),M9&" "&$M$7&" / ","")&IF(AND(N9<>"",N9>0),N9&" "&$N$7&" / ","")&IF(AND(O9<>"",O9>0),O9&" "&$O$7&" / ","")&IF(AND(P9<>"",P9>0),P9&" "&$P$7&" / ",""))-2))) | S9: =IF(ISBLANK($A9),"",IF(ISBLANK(VLOOKUP($A9,Tableau6[],17,FALSE)),"",VLOOKUP($A9,Tableau6[],17,FALSE))) | T9: =IF(ISBLANK($A9),"",IF(ISBLANK(VLOOKUP($A9,Tableau6[],18,FALSE)),"",VLOOKUP($A9,Tableau6[],18,FALSE))) | U9: =IF(AND(OR(S9="",S9=0),OR(T9="",T9=0)),"",TRIM(LEFT(IF(AND(S9<>"",S9>0),S9&" "&$S$7&" / ","")&IF(AND(T9<>"",T9>0),T9&" "&$T$7&" / ",""),LEN(IF(AND(S9<>"",S9>0),S9&" "&$S$7&" / ","")&IF(AND(T9<>"",T9>0),T9&" "&$T$7&" / ",""))-2))) | V9: =IF(ISBLANK($A9),"",IF(ISBLANK(VLOOKUP($A9,Tableau6[],19,FALSE)),"",VLOOKUP($A9,Tableau6[],19,FALSE))) | W9: =IF(ISBLANK($A9),"",IF(ISBLANK(VLOOKUP($A9,Tableau6[],20,FALSE)),"",VLOOKUP($A9,Tableau6[],20,FALSE))) | X9: =IF(ISBLANK($A9),"",IF(ISBLANK(VLOOKUP($A9,Tableau6[],21,FALSE)),"",VLOOKUP($A9,Tableau6[],21,FALSE))) | Y9: =IF(AND(OR(V9="",V9=0),OR(W9="",W9=0),OR(X9="",X9=0)),"",TRIM(LEFT(IF(AND(V9<>"",V9>0),V9&" "&$V$7&" / ","")&IF(AND(W9<>"",W9>0),W9&" "&$W$7&" / ","")&IF(AND(X9<>"",X9>0),X9&" "&" / ",""),LEN(IF(AND(V9<>"",V9>0),V9&" "&$V$7&" / ","")&IF(AND(W9<>"",W9>0),W9&" "&$W$7&" / ","")&IF(AND(X9<>"",X9>0),X9&" "&" / ",""))-2))) | Z9: =IF(ISBLANK($A9),"",IF(ISBLANK(VLOOKUP($A9,Tableau6[],22,FALSE)),"",VLOOKUP($A9,Tableau6[],22,FALSE))) | AA9: =IF(ISBLANK($A9),"",IF(ISBLANK(VLOOKUP($A9,Tableau6[],23,FALSE)),"",VLOOKUP($A9,Tableau6[],23,FALSE))) | AB9: =IF(ISBLANK($A9),"",IF(ISBLANK(VLOOKUP($A9,Tableau6[],24,FALSE)),"",VLOOKUP($A9,Tableau6[],24,FALSE))) | AC9: =IF(AND(OR(Z9="",Z9=0),OR(AA9="",AA9=0),OR(AB9="",AB9=0)),"",TRIM(LEFT(IF(AND(Z9<>"",Z9>0),Z9&" "&$Z$7&" / ","")&IF(AND(AA9<>"",AA9>0),AA9&" "&$AA$7&" / ","")&IF(AND(AB9<>"",AB9>0),AB9&" "&" / ",""),LEN(IF(AND(Z9<>"",Z9>0),Z9&" "&$Z$7&" / ","")&IF(AND(AA9<>"",AA9>0),AA9&" "&$AA$7&" / ","")&IF(AND(AB9<>"",AB9>0),AB9&" "&" / ",""))-2))) | AD9: =IF(ISBLANK($A9),"",IF(ISBLANK(VLOOKUP($A9,Tableau6[],25,FALSE)),"",VLOOKUP($A9,Tableau6[],25,FALSE))) | AE9: =IF(ISBLANK($A9),"",IF(ISBLANK(VLOOKUP($A9,Tableau6[],26,FALSE)),"",VLOOKUP($A9,Tableau6[],26,FALSE))) | AF9: =IF(ISBLANK($A9),"",IF(ISBLANK(VLOOKUP($A9,Tableau6[],27,FALSE)),"",VLOOKUP($A9,Tableau6[],27,FALSE))) | AG9: =IF(AND(OR(AD9="",AD9=0),OR(AE9="",AE9=0),OR(AF9="",AF9=0)),"",TRIM(LEFT(IF(AND(AD9<>"",AD9>0),AD9&" "&$AD$7&" / ","")&IF(AND(AE9<>"",AE9>0),AE9&" "&$AE$7&" / ","")&IF(AND(AF9<>"",AF9>0),AF9&" "&$AF$7&" / ",""),LEN(IF(AND(AD9<>"",AD9>0),AD9&" "&$AD$7&" / ","")&IF(AND(AE9<>"",AE9>0),AE9&" "&$AE$7&" / ","")&IF(AND(AF9<>"",AF9>0),AF9&" "&$AF$7&" / ",""))-2))) | AH9: =IF(ISBLANK($A9),"",IF(ISBLANK(VLOOKUP($A9,Tableau6[],28,FALSE)),"",VLOOKUP($A9,Tableau6[],28,FALSE))) | AI9: =IF(ISBLANK($A9),"",IF(ISBLANK(VLOOKUP($A9,Tableau6[],29,FALSE)),"",VLOOKUP($A9,Tableau6[],29,FALSE))) | AJ9: =IF(ISBLANK($A9),"",IF(ISBLANK(VLOOKUP($A9,Tableau6[],30,FALSE)),"",VLOOKUP($A9,Tableau6[],30,FALSE))) | AK9: =IF(AND(OR(AI9="",AI9=0),OR(AJ9="",AJ9=0)),"",TRIM(LEFT(IF(AND(AI9<>"",AI9>0),AI9&" "&$AI$7&" / ","")&IF(AND(AJ9<>"",AJ9>0),AJ9&" "&$AJ$7&" / ",""),LEN(IF(AND(AI9<>"",AI9>0),AI9&" "&$AI$7&" / ","")&IF(AND(AJ9<>"",AJ9>0),AJ9&" "&$AJ$7&" / ",""))-2))) | AL9: =IF(ISBLANK($A9),"",IF(ISBLANK(VLOOKUP($A9,Tableau6[],31,FALSE)),"",VLOOKUP($A9,Tableau6[],31,FALSE))) | AM9: =IF(ISBLANK($A9),"",IF(ISBLANK(VLOOKUP($A9,Tableau6[],32,FALSE)),"",VLOOKUP($A9,Tableau6[],32,FALSE))) | AN9: =IF(ISBLANK($A9),"",IF(ISBLANK(VLOOKUP($A9,Tableau6[],33,FALSE)),"",VLOOKUP($A9,Tableau6[],33,FALSE))) | AO9: =IF(ISBLANK($A9),"",IF(ISBLANK(VLOOKUP($A9,Tableau6[],34,FALSE)),"",VLOOKUP($A9,Tableau6[],34,FALSE))) | AP9: =IF(ISBLANK($A9),"",IF(ISBLANK(VLOOKUP($A9,Tableau6[],35,FALSE)),"",VLOOKUP($A9,Tableau6[],35,FALSE))) | AQ9: =IF(ISBLANK($A9),"",IF(ISBLANK(VLOOKUP($A9,Tableau6[],36,FALSE)),"",VLOOKUP($A9,Tableau6[],36,FALSE))) | AR9: =IF(ISBLANK($A9),"",IF(ISBLANK(VLOOKUP($A9,Tableau6[],37,FALSE)),"",VLOOKUP($A9,Tableau6[],37,FALSE))) | AS9: =IF(ISBLANK($A9),"",IF(ISBLANK(VLOOKUP($A9,Tableau6[],38,FALSE)),"",VLOOKUP($A9,Tableau6[],38,FALSE))) -> 1 | AT9: =IF(ISBLANK($A9),"",IF(ISBLANK(VLOOKUP($A9,Tableau6[],39,FALSE)),"",VLOOKUP($A9,Tableau6[],39,FALSE))) | AU9: =IF(ISBLANK($A9),"",IF(ISBLANK(VLOOKUP($A9,Tableau6[],40,FALSE)),"",VLOOKUP($A9,Tableau6[],40,FALSE))) | AV9: =IF(ISBLANK($A9),"",IF(ISBLANK(VLOOKUP($A9,Tableau6[],41,FALSE)),"",VLOOKUP($A9,Tableau6[],41,FALSE))) | AW9: =IF(ISBLANK($A9),"",IF(ISBLANK(VLOOKUP($A9,Tableau6[],42,FALSE)),"",VLOOKUP($A9,Tableau6[],42,FALSE))) | AX9: =IF(ISBLANK($A9),"",IF(ISBLANK(VLOOKUP($A9,Tableau6[],43,FALSE)),"",VLOOKUP($A9,Tableau6[],43,FALSE))) -> 84 | AY9: =IF(ISBLANK($A9),"",IF(ISBLANK(VLOOKUP($A9,Tableau6[],44,FALSE)),"",VLOOKUP($A9,Tableau6[],44,FALSE))) | AZ9: =IF(ISBLANK($A9),"",IF(ISBLANK(VLOOKUP($A9,Tableau6[],45,FALSE)),"",VLOOKUP($A9,Tableau6[],45,FALSE))) | BA9: =IF(ISBLANK($A9),"",IF(ISBLANK(VLOOKUP($A9,Tableau6[],46,FALSE)),"",VLOOKUP($A9,Tableau6[],46,FALSE))) | BB9: =IF(AND(OR(AK9="",AK9=0),OR(AL9="",AL9=0),OR(AM9="",AM9=0),OR(AN9="",AN9=0),OR(AO9="",AO9=0),OR(AP9="",AP9=0),OR(AQ9="",AQ9=0),OR(AR9="",AR9=0),OR(AS9="",AS9=0),OR(AT9="",AT9=0),OR(AU9="",AU9=0),OR(AV9="",AV9=0),OR(AW9="",AW9=0),OR(AX9="",AX9=0),OR(AY9="",AY9=0),OR(AZ9="",AZ9=0),OR(BA9="",BA9=0)),"",TRIM(LEFT(IF(AND(AK9<>"",AK9>0),AK9&" "&$AK$7&" / ","")&IF(AND(AL9<>"",AL9>0),AL9&" "&$AL$7&" / ","")&IF(AND(AM9<>"",AM9>0),AM9&" "&$AM$7&" / ","")&IF(AND(AN9<>"",AN9>0),AN9&" "&$AN$7&" / ","")&IF(AND(AO9<>"",AO9>0),AO9&" "&$AO$7&" / ","")&IF(AND(AP9<>"",AP9>0),AP9&" "&$AP$7&" / ","")&IF(AND(AQ9<>"",AQ9>0),AQ9&" "&$AQ$7&" / ","")&IF(AND(AR9<>"",AR9>0),AR9&" "&$AR$7&" / ","")&IF(AND(AS9<>"",AS9>0),AS9&" "&$AS$7&" / ","")&IF(AND(AT9<>"",AT9>0),AT9&" "&$AT$7&" / ","")&IF(AND(AU9<>"",AU9>0),AU9&" "&$AU$7&" / ","")&IF(AND(AV9<>"",AV9>0),AV9&" "&$AV$7&" / ","")&IF(AND(AW9<>"",AW9>0),AW9&" "&$AW$7&" / ","")&IF(AND(AX9<>"",AX9>0),AX9&" "&$AX$7&" / ","")&IF(AND(AY9<>"",AY9>0),AY9&" "&$AY$7&" / ","")&IF(AND(AZ9<>"",AZ9>0),AZ9&" "&$AZ$7&" / ","")&IF(AND(BA9<>"",BA9>0),BA9&" "&" / ",""),LEN(IF(AND(AK9<>"",AK9>0),AK9&" "&$AK$7&" / ","")&IF(AND(AL9<>"",AL9>0),AL9&" "&$AL$7&" / ","")&IF(AND(AM9<>"",AM9>0),AM9&" "&$AM$7&" / ","")&IF(AND(AN9<>"",AN9>0),AN9&" "&$AN$7&" / ","")&IF(AND(AO9<>"",AO9>0),AO9&" "&$AO$7&" / ","")&IF(AND(AP9<>"",AP9>0),AP9&" "&$AP$7&" / ","")&IF(AND(AQ9<>"",AQ9>0),AQ9&" "&$AQ$7&" / ","")&IF(AND(AR9<>"",AR9>0),AR9&" "&$AR$7&" / ","")&IF(AND(AS9<>"",AS9>0),AS9&" "&$AS$7&" / ","")&IF(AND(AT9<>"",AT9>0),AT9&" "&$AT$7&" / ","")&IF(AND(AU9<>"",AU9>0),AU9&" "&$AU$7&" / ","")&IF(AND(AV9<>"",AV9>0),AV9&" "&$AV$7&" / ","")&IF(AND(AW9<>"",AW9>0),AW9&" "&$AW$7&" / ","")&IF(AND(AX9<>"",AX9>0),AX9&" "&$AX$7&" / ","")&IF(AND(AY9<>"",AY9>0),AY9&" "&$AY$7&" / ","")&IF(AND(AZ9<>"",AZ9>0),AZ9&" "&$AZ$7&" / ","")&IF(AND(BA9<>"",BA9>0),BA9&" "" / ",""))-2))) -> 1 ميزان / 84 د.التونسي
A10: المنستير | B10: =IF(ISBLANK($A10),"",IF(ISBLANK(VLOOKUP($A10,Tableau6[],2,FALSE)),"",VLOOKUP($A10,Tableau6[],2,FALSE))) -> منزل النور | C10: =IF(ISBLANK($A10),"",IF(ISBLANK(VLOOKUP($A10,Tableau6[],3,FALSE)),"",VLOOKUP($A10,Tableau6[],3,FALSE))) -> 1 | D10: =IF(ISBLANK($A10),"",IF(ISBLANK(VLOOKUP($A10,Tableau6[],4,FALSE)),"",VLOOKUP($A10,Tableau6[],4,FALSE))) -> 1 | E10: =IF(ISBLANK($A10),"",IF(ISBLANK(VLOOKUP($A10,Tableau6[],5,FALSE)),"",VLOOKUP($A10,Tableau6[],5,FALSE))) | F10: =IF(ISBLANK($A10),"",IF(ISBLANK(VLOOKUP($A10,Tableau6[],6,FALSE)),"",VLOOKUP($A10,Tableau6[],6,FALSE))) | G10: =IF(ISBLANK($A10),"",IF(ISBLANK(VLOOKUP($A10,Tableau6[],7,FALSE)),"",VLOOKUP($A10,Tableau6[],7,FALSE))) | H10: =IF(ISBLANK($A10),"",IF(ISBLANK(VLOOKUP($A10,Tableau6[],8,FALSE)),"",VLOOKUP($A10,Tableau6[],8,FALSE))) -> 2 | I10: =IF(ISBLANK($A10),"",IF(ISBLANK(VLOOKUP($A10,Tableau6[],9,FALSE)),"",VLOOKUP($A10,Tableau6[],9,FALSE))) | J10: =IF(ISBLANK($A10),"",IF(ISBLANK(VLOOKUP($A10,Tableau6[],10,FALSE)),"",VLOOKUP($A10,Tableau6[],10,FALSE))) | K10: =IF(ISBLANK($A10),"",IF(ISBLANK(VLOOKUP($A10,Tableau6[],11,FALSE)),"",VLOOKUP($A10,Tableau6[],11,FALSE))) | L10: =IF(ISBLANK($A10),"",IF(ISBLANK(VLOOKUP($A10,Tableau6[],12,FALSE)),"",VLOOKUP($A10,Tableau6[],12,FALSE))) | M10: =IF(ISBLANK($A10),"",IF(ISBLANK(VLOOKUP($A10,Tableau6[],13,FALSE)),"",VLOOKUP($A10,Tableau6[],13,FALSE))) | N10: =IF(ISBLANK($A10),"",IF(ISBLANK(VLOOKUP($A10,Tableau6[],14,FALSE)),"",VLOOKUP($A10,Tableau6[],14,FALSE))) | O10: =IF(ISBLANK($A10),"",IF(ISBLANK(VLOOKUP($A10,Tableau6[],15,FALSE)),"",VLOOKUP($A10,Tableau6[],15,FALSE))) | P10: =IF(ISBLANK($A10),"",IF(ISBLANK(VLOOKUP($A10,Tableau6[],16,FALSE)),"",VLOOKUP($A10,Tableau6[],16,FALSE))) | R10: =IF(AND(OR(L10="",L10=0),OR(M10="",M10=0),OR(N10="",N10=0),OR(O10="",O10=0)*OR(P10="",P10=0)),"",TRIM(LEFT(IF(AND(L10<>"",L10>0),L10&" "&$L$7&" / ","")&IF(AND(M10<>"",M10>0),M10&" "&$M$7&" / ","")&IF(AND(N10<>"",N10>0),N10&" "&$N$7&" / ","")&IF(AND(O10<>"",O10>0),O10&" "&$O$7&" / ","")&IF(AND(P10<>"",P10>0),P10&" "&$P$7&" / ",""),LEN(IF(AND(L10<>"",L10>0),L10&" "&$L$7&" / ","")&IF(AND(M10<>"",M10>0),M10&" "&$M$7&" / ","")&IF(AND(N10<>"",N10>0),N10&" "&$N$7&" / ","")&IF(AND(O10<>"",O10>0),O10&" "&$O$7&" / ","")&IF(AND(P10<>"",P10>0),P10&" "&$P$7&" / ",""))-2))) | S10: =IF(ISBLANK($A10),"",IF(ISBLANK(VLOOKUP($A10,Tableau6[],17,FALSE)),"",VLOOKUP($A10,Tableau6[],17,FALSE))) | T10: =IF(ISBLANK($A10),"",IF(ISBLANK(VLOOKUP($A10,Tableau6[],18,FALSE)),"",VLOOKUP($A10,Tableau6[],18,FALSE))) | U10: =IF(AND(OR(S10="",S10=0),OR(T10="",T10=0)),"",TRIM(LEFT(IF(AND(S10<>"",S10>0),S10&" "&$S$7&" / ","")&IF(AND(T10<>"",T10>0),T10&" "&$T$7&" / ",""),LEN(IF(AND(S10<>"",S10>0),S10&" "&$S$7&" / ","")&IF(AND(T10<>"",T10>0),T10&" "&$T$7&" / ",""))-2))) | V10: =IF(ISBLANK($A10),"",IF(ISBLANK(VLOOKUP($A10,Tableau6[],19,FALSE)),"",VLOOKUP($A10,Tableau6[],19,FALSE))) | W10: =IF(ISBLANK($A10),"",IF(ISBLANK(VLOOKUP($A10,Tableau6[],20,FALSE)),"",VLOOKUP($A10,Tableau6[],20,FALSE))) | X10: =IF(ISBLANK($A10),"",IF(ISBLANK(VLOOKUP($A10,Tableau6[],21,FALSE)),"",VLOOKUP($A10,Tableau6[],21,FALSE))) | Y10: =IF(AND(OR(V10="",V10=0),OR(W10="",W10=0),OR(X10="",X10=0)),"",TRIM(LEFT(IF(AND(V10<>"",V10>0),V10&" "&$V$7&" / ","")&IF(AND(W10<>"",W10>0),W10&" "&$W$7&" / ","")&IF(AND(X10<>"",X10>0),X10&" "&" / ",""),LEN(IF(AND(V10<>"",V10>0),V10&" "&$V$7&" / ","")&IF(AND(W10<>"",W10>0),W10&" "&$W$7&" / ","")&IF(AND(X10<>"",X10>0),X10&" "&" / ",""))-2))) | Z10: =IF(ISBLANK($A10),"",IF(ISBLANK(VLOOKUP($A10,Tableau6[],22,FALSE)),"",VLOOKUP($A10,Tableau6[],22,FALSE))) | AA10: =IF(ISBLANK($A10),"",IF(ISBLANK(VLOOKUP($A10,Tableau6[],23,FALSE)),"",VLOOKUP($A10,Tableau6[],23,FALSE))) | AB10: =IF(ISBLANK($A10),"",IF(ISBLANK(VLOOKUP($A10,Tableau6[],24,FALSE)),"",VLOOKUP($A10,Tableau6[],24,FALSE))) | AC10: =IF(AND(OR(Z10="",Z10=0),OR(AA10="",AA10=0),OR(AB10="",AB10=0)),"",TRIM(LEFT(IF(AND(Z10<>"",Z10>0),Z10&" "&$Z$7&" / ","")&IF(AND(AA10<>"",AA10>0),AA10&" "&$AA$7&" / ","")&IF(AND(AB10<>"",AB10>0),AB10&" "&" / ",""),LEN(IF(AND(Z10<>"",Z10>0),Z10&" "&$Z$7&" / ","")&IF(AND(AA10<>"",AA10>0),AA10&" "&$AA$7&" / ","")&IF(AND(AB10<>"",AB10>0),AB10&" "&" / ",""))-2))) | AD10: =IF(ISBLANK($A10),"",IF(ISBLANK(VLOOKUP($A10,Tableau6[],25,FALSE)),"",VLOOKUP($A10,Tableau6[],25,FALSE))) | AE10: =IF(ISBLANK($A10),"",IF(ISBLANK(VLOOKUP($A10,Tableau6[],26,FALSE)),"",VLOOKUP($A10,Tableau6[],26,FALSE))) | AF10: =IF(ISBLANK($A10),"",IF(ISBLANK(VLOOKUP($A10,Tableau6[],27,FALSE)),"",VLOOKUP($A10,Tableau6[],27,FALSE))) | AG10: =IF(AND(OR(AD10="",AD10=0),OR(AE10="",AE10=0),OR(AF10="",AF10=0)),"",TRIM(LEFT(IF(AND(AD10<>"",AD10>0),AD10&" "&$AD$7&" / ","")&IF(AND(AE10<>"",AE10>0),AE10&" "&$AE$7&" / ","")&IF(AND(AF10<>"",AF10>0),AF10&" "&$AF$7&" / ",""),LEN(IF(AND(AD10<>"",AD10>0),AD10&" "&$AD$7&" / ","")&IF(AND(AE10<>"",AE10>0),AE10&" "&$AE$7&" / ","")&IF(AND(AF10<>"",AF10>0),AF10&" "&$AF$7&" / ",""))-2))) | AH10: =IF(ISBLANK($A10),"",IF(ISBLANK(VLOOKUP($A10,Tableau6[],28,FALSE)),"",VLOOKUP($A10,Tableau6[],28,FALSE))) | AI10: =IF(ISBLANK($A10),"",IF(ISBLANK(VLOOKUP($A10,Tableau6[],29,FALSE)),"",VLOOKUP($A10,Tableau6[],29,FALSE))) | AJ10: =IF(ISBLANK($A10),"",IF(ISBLANK(VLOOKUP($A10,Tableau6[],30,FALSE)),"",VLOOKUP($A10,Tableau6[],30,FALSE))) | AK10: =IF(AND(OR(AI10="",AI10=0),OR(AJ10="",AJ10=0)),"",TRIM(LEFT(IF(AND(AI10<>"",AI10>0),AI10&" "&$AI$7&" / ","")&IF(AND(AJ10<>"",AJ10>0),AJ10&" "&$AJ$7&" / ",""),LEN(IF(AND(AI10<>"",AI10>0),AI10&" "&$AI$7&" / ","")&IF(AND(AJ10<>"",AJ10>0),AJ10&" "&$AJ$7&" / ",""))-2))) | AL10: =IF(ISBLANK($A10),"",IF(ISBLANK(VLOOKUP($A10,Tableau6[],31,FALSE)),"",VLOOKUP($A10,Tableau6[],31,FALSE))) | AM10: =IF(ISBLANK($A10),"",IF(ISBLANK(VLOOKUP($A10,Tableau6[],32,FALSE)),"",VLOOKUP($A10,Tableau6[],32,FALSE))) | AN10: =IF(ISBLANK($A10),"",IF(ISBLANK(VLOOKUP($A10,Tableau6[],33,FALSE)),"",VLOOKUP($A10,Tableau6[],33,FALSE))) | AO10: =IF(ISBLANK($A10),"",IF(ISBLANK(VLOOKUP($A10,Tableau6[],34,FALSE)),"",VLOOKUP($A10,Tableau6[],34,FALSE))) | AP10: =IF(ISBLANK($A10),"",IF(ISBLANK(VLOOKUP($A10,Tableau6[],35,FALSE)),"",VLOOKUP($A10,Tableau6[],35,FALSE))) | AQ10: =IF(ISBLANK($A10),"",IF(ISBLANK(VLOOKUP($A10,Tableau6[],36,FALSE)),"",VLOOKUP($A10,Tableau6[],36,FALSE))) | AR10: =IF(ISBLANK($A10),"",IF(ISBLANK(VLOOKUP($A10,Tableau6[],37,FALSE)),"",VLOOKUP($A10,Tableau6[],37,FALSE))) -> 1 | AS10: =IF(ISBLANK($A10),"",IF(ISBLANK(VLOOKUP($A10,Tableau6[],38,FALSE)),"",VLOOKUP($A10,Tableau6[],38,FALSE))) | AT10: =IF(ISBLANK($A10),"",IF(ISBLANK(VLOOKUP($A10,Tableau6[],39,FALSE)),"",VLOOKUP($A10,Tableau6[],39,FALSE))) | AU10: =IF(ISBLANK($A10),"",IF(ISBLANK(VLOOKUP($A10,Tableau6[],40,FALSE)),"",VLOOKUP($A10,Tableau6[],40,FALSE))) | AV10: =IF(ISBLANK($A10),"",IF(ISBLANK(VLOOKUP($A10,Tableau6[],41,FALSE)),"",VLOOKUP($A10,Tableau6[],41,FALSE))) | AW10: =IF(ISBLANK($A10),"",IF(ISBLANK(VLOOKUP($A10,Tableau6[],42,FALSE)),"",VLOOKUP($A10,Tableau6[],42,FALSE))) | AX10: =IF(ISBLANK($A10),"",IF(ISBLANK(VLOOKUP($A10,Tableau6[],43,FALSE)),"",VLOOKUP($A10,Tableau6[],43,FALSE))) | AY10: =IF(ISBLANK($A10),"",IF(ISBLANK(VLOOKUP($A10,Tableau6[],44,FALSE)),"",VLOOKUP($A10,Tableau6[],44,FALSE))) | AZ10: =IF(ISBLANK($A10),"",IF(ISBLANK(VLOOKUP($A10,Tableau6[],45,FALSE)),"",VLOOKUP($A10,Tableau6[],45,FALSE))) | BA10: =IF(ISBLANK($A10),"",IF(ISBLANK(VLOOKUP($A10,Tableau6[],46,FALSE)),"",VLOOKUP($A10,Tableau6[],46,FALSE))) | BB10: =IF(AND(OR(AK10="",AK10=0),OR(AL10="",AL10=0),OR(AM10="",AM10=0),OR(AN10="",AN10=0),OR(AO10="",AO10=0),OR(AP10="",AP10=0),OR(AQ10="",AQ10=0),OR(AR10="",AR10=0),OR(AS10="",AS10=0),OR(AT10="",AT10=0),OR(AU10="",AU10=0),OR(AV10="",AV10=0),OR(AW10="",AW10=0),OR(AX10="",AX10=0),OR(AY10="",AY10=0),OR(AZ10="",AZ10=0),OR(BA10="",BA10=0)),"",TRIM(LEFT(IF(AND(AK10<>"",AK10>0),AK10&" "&$AK$7&" / ","")&IF(AND(AL10<>"",AL10>0),AL10&" "&$AL$7&" / ","")&IF(AND(AM10<>"",AM10>0),AM10&" "&$AM$7&" / ","")&IF(AND(AN10<>"",AN10>0),AN10&" "&$AN$7&" / ","")&IF(AND(AO10<>"",AO10>0),AO10&" "&$AO$7&" / ","")&IF(AND(AP10<>"",AP10>0),AP10&" "&$AP$7&" / ","")&IF(AND(AQ10<>"",AQ10>0),AQ10&" "&$AQ$7&" / ","")&IF(AND(AR10<>"",AR10>0),AR10&" "&$AR$7&" / ","")&IF(AND(AS10<>"",AS10>0),AS10&" "&$AS$7&" / ","")&IF(AND(AT10<>"",AT10>0),AT10&" "&$AT$7&" / ","")&IF(AND(AU10<>"",AU10>0),AU10&" "&$AU$7&" / ","")&IF(AND(AV10<>"",AV10>0),AV10&" "&$AV$7&" / ","")&IF(AND(AW10<>"",AW10>0),AW10&" "&$AW$7&" / ","")&IF(AND(AX10<>"",AX10>0),AX10&" "&$AX$7&" / ","")&IF(AND(AY10<>"",AY10>0),AY10&" "&$AY$7&" / ","")&IF(AND(AZ10<>"",AZ10>0),AZ10&" "&$AZ$7&" / ","")&IF(AND(BA10<>"",BA10>0),BA10&" "&" / ",""),LEN(IF(AND(AK10<>"",AK10>0),AK10&" "&$AK$7&" / ","")&IF(AND(AL10<>"",AL10>0),AL10&" "&$AL$7&" / ","")&IF(AND(AM10<>"",AM10>0),AM10&" "&$AM$7&" / ","")&IF(AND(AN10<>"",AN10>0),AN10&" "&$AN$7&" / ","")&IF(AND(AO10<>"",AO10>0),AO10&" "&$AO$7&" / ","")&IF(AND(AP10<>"",AP10>0),AP10&" "&$AP$7&" / ","")&IF(AND(AQ10<>"",AQ10>0),AQ10&" "&$AQ$7&" / ","")&IF(AND(AR10<>"",AR10>0),AR10&" "&$AR$7&" / ","")&IF(AND(AS10<>"",AS10>0),AS10&" "&$AS$7&" / ","")&IF(AND(AT10<>"",AT10>0),AT10&" "&$AT$7&" / ","")&IF(AND(AU10<>"",AU10>0),AU10&" "&$AU$7&" / ","")&IF(AND(AV10<>"",AV10>0),AV10&" "&$AV$7&" / ","")&IF(AND(AW10<>"",AW10>0),AW10&" "&$AW$7&" / ","")&IF(AND(AX10<>"",AX10>0),AX10&" "&$AX$7&" / ","")&IF(AND(AY10<>"",AY10>0),AY10&" "&$AY$7&" / ","")&IF(AND(AZ10<>"",AZ10>0),AZ10&" "&$AZ$7&" / ","")&IF(AND(BA10<>"",BA10>0),BA10&" "" / ",""))-2))) -> 1 صحن
A11: الفرق المركزية للأبحاث | B11: =IF(ISBLANK($A11),"",IF(ISBLANK(VLOOKUP($A11,Tableau6[],2,FALSE)),"",VLOOKUP($A11,Tableau6[],2,FALSE))) -> العوينة | C11: =IF(ISBLANK($A11),"",IF(ISBLANK(VLOOKUP($A11,Tableau6[],3,FALSE)),"",VLOOKUP($A11,Tableau6[],3,FALSE))) -> 1 | D11: =IF(ISBLANK($A11),"",IF(ISBLANK(VLOOKUP($A11,Tableau6[],4,FALSE)),"",VLOOKUP($A11,Tableau6[],4,FALSE))) | E11: =IF(ISBLANK($A11),"",IF(ISBLANK(VLOOKUP($A11,Tableau6[],5,FALSE)),"",VLOOKUP($A11,Tableau6[],5,FALSE))) -> 1 | F11: =IF(ISBLANK($A11),"",IF(ISBLANK(VLOOKUP($A11,Tableau6[],6,FALSE)),"",VLOOKUP($A11,Tableau6[],6,FALSE))) | G11: =IF(ISBLANK($A11),"",IF(ISBLANK(VLOOKUP($A11,Tableau6[],7,FALSE)),"",VLOOKUP($A11,Tableau6[],7,FALSE))) | H11: =IF(ISBLANK($A11),"",IF(ISBLANK(VLOOKUP($A11,Tableau6[],8,FALSE)),"",VLOOKUP($A11,Tableau6[],8,FALSE))) | I11: =IF(ISBLANK($A11),"",IF(ISBLANK(VLOOKUP($A11,Tableau6[],9,FALSE)),"",VLOOKUP($A11,Tableau6[],9,FALSE))) -> 1 | J11: =IF(ISBLANK($A11),"",IF(ISBLANK(VLOOKUP($A11,Tableau6[],10,FALSE)),"",VLOOKUP($A11,Tableau6[],10,FALSE))) | K11: =IF(ISBLANK($A11),"",IF(ISBLANK(VLOOKUP($A11,Tableau6[],11,FALSE)),"",VLOOKUP($A11,Tableau6[],11,FALSE))) | L11: =IF(ISBLANK($A11),"",IF(ISBLANK(VLOOKUP($A11,Tableau6[],12,FALSE)),"",VLOOKUP($A11,Tableau6[],12,FALSE))) | M11: =IF(ISBLANK($A11),"",IF(ISBLANK(VLOOKUP($A11,Tableau6[],13,FALSE)),"",VLOOKUP($A11,Tableau6[],13,FALSE))) | N11: =IF(ISBLANK($A11),"",IF(ISBLANK(VLOOKUP($A11,Tableau6[],14,FALSE)),"",VLOOKUP($A11,Tableau6[],14,FALSE))) -> 1 | O11: =IF(ISBLANK($A11),"",IF(ISBLANK(VLOOKUP($A11,Tableau6[],15,FALSE)),"",VLOOKUP($A11,Tableau6[],15,FALSE))) | P11: =IF(ISBLANK($A11),"",IF(ISBLANK(VLOOKUP($A11,Tableau6[],16,FALSE)),"",VLOOKUP($A11,Tableau6[],16,FALSE))) | R11: =IF(AND(OR(L11="",L11=0),OR(M11="",M11=0),OR(N11="",N11=0),OR(O11="",O11=0)*OR(P11="",P11=0)),"",TRIM(LEFT(IF(AND(L11<>"",L11>0),L11&" "&$L$7&" / ","")&IF(AND(M11<>"",M11>0),M11&" "&$M$7&" / ","")&IF(AND(N11<>"",N11>0),N11&" "&$N$7&" / ","")&IF(AND(O11<>"",O11>0),O11&" "&$O$7&" / ","")&IF(AND(P11<>"",P11>0),P11&" "&$P$7&" / ",""),LEN(IF(AND(L11<>"",L11>0),L11&" "&$L$7&" / ","")&IF(AND(M11<>"",M11>0),M11&" "&$M$7&" / ","")&IF(AND(N11<>"",N11>0),N11&" "&$N$7&" / ","")&IF(AND(O11<>"",O11>0),O11&" "&$O$7&" / ","")&IF(AND(P11<>"",P11>0),P11&" "&$P$7&" / ",""))-2))) -> 1 قطع | S11: =IF(ISBLANK($A11),"",IF(ISBLANK(VLOOKUP($A11,Tableau6[],17,FALSE)),"",VLOOKUP($A11,Tableau6[],17,FALSE))) -> 22 | T11: =IF(ISBLANK($A11),"",IF(ISBLANK(VLOOKUP($A11,Tableau6[],18,FALSE)),"",VLOOKUP($A11,Tableau6[],18,FALSE))) | U11: =IF(AND(OR(S11="",S11=0),OR(T11="",T11=0)),"",TRIM(LEFT(IF(AND(S11<>"",S11>0),S11&" "&$S$7&" / ","")&IF(AND(T11<>"",T11>0),T11&" "&$T$7&" / ",""),LEN(IF(AND(S11<>"",S11>0),S11&" "&$S$7&" / ","")&IF(AND(T11<>"",T11>0),T11&" "&$T$7&" / ",""))-2))) -> 22 قرص | V11: =IF(ISBLANK($A11),"",IF(ISBLANK(VLOOKUP($A11,Tableau6[],19,FALSE)),"",VLOOKUP($A11,Tableau6[],19,FALSE))) | W11: =IF(ISBLANK($A11),"",IF(ISBLANK(VLOOKUP($A11,Tableau6[],20,FALSE)),"",VLOOKUP($A11,Tableau6[],20,FALSE))) | X11: =IF(ISBLANK($A11),"",IF(ISBLANK(VLOOKUP($A11,Tableau6[],21,FALSE)),"",VLOOKUP($A11,Tableau6[],21,FALSE))) | Y11: =IF(AND(OR(V11="",V11=0),OR(W11="",W11=0),OR(X11="",X11=0)),"",TRIM(LEFT(IF(AND(V11<>"",V11>0),V11&" "&$V$7&" / ","")&IF(AND(W11<>"",W11>0),W11&" "&$W$7&" / ","")&IF(AND(X11<>"",X11>0),X11&" "&" / ",""),LEN(IF(AND(V11<>"",V11>0),V11&" "&$V$7&" / ","")&IF(AND(W11<>"",W11>0),W11&" "&$W$7&" / ","")&IF(AND(X11<>"",X11>0),X11&" "&" / ",""))-2))) | Z11: =IF(ISBLANK($A11),"",IF(ISBLANK(VLOOKUP($A11,Tableau6[],22,FALSE)),"",VLOOKUP($A11,Tableau6[],22,FALSE))) | AA11: =IF(ISBLANK($A11),"",IF(ISBLANK(VLOOKUP($A11,Tableau6[],23,FALSE)),"",VLOOKUP($A11,Tableau6[],23,FALSE))) | AB11: =IF(ISBLANK($A11),"",IF(ISBLANK(VLOOKUP($A11,Tableau6[],24,FALSE)),"",VLOOKUP($A11,Tableau6[],24,FALSE))) | AC11: =IF(AND(OR(Z11="",Z11=0),OR(AA11="",AA11=0),OR(AB11="",AB11=0)),"",TRIM(LEFT(IF(AND(Z11<>"",Z11>0),Z11&" "&$Z$7&" / ","")&IF(AND(AA11<>"",AA11>0),AA11&" "&$AA$7&" / ","")&IF(AND(AB11<>"",AB11>0),AB11&" "&" / ",""),LEN(IF(AND(Z11<>"",Z11>0),Z11&" "&$Z$7&" / ","")&IF(AND(AA11<>"",AA11>0),AA11&" "&$AA$7&" / ","")&IF(AND(AB11<>"",AB11>0),AB11&" "&" / ",""))-2))) | AD11: =IF(ISBLANK($A11),"",IF(ISBLANK(VLOOKUP($A11,Tableau6[],25,FALSE)),"",VLOOKUP($A11,Tableau6[],25,FALSE))) | AE11: =IF(ISBLANK($A11),"",IF(ISBLANK(VLOOKUP($A11,Tableau6[],26,FALSE)),"",VLOOKUP($A11,Tableau6[],26,FALSE))) | AF11: =IF(ISBLANK($A11),"",IF(ISBLANK(VLOOKUP($A11,Tableau6[],27,FALSE)),"",VLOOKUP($A11,Tableau6[],27,FALSE))) | AG11: =IF(AND(OR(AD11="",AD11=0),OR(AE11="",AE11=0),OR(AF11="",AF11=0)),"",TRIM(LEFT(IF(AND(AD11<>"",AD11>0),AD11&" "&$AD$7&" / ","")&IF(AND(AE11<>"",AE11>0),AE11&" "&$AE$7&" / ","")&IF(AND(AF11<>"",AF11>0),AF11&" "&$AF$7&" / ",""),LEN(IF(AND(AD11<>"",AD11>0),AD11&" "&$AD$7&" / ","")&IF(AND(AE11<>"",AE11>0),AE11&" "&$AE$7&" / ","")&IF(AND(AF11<>"",AF11>0),AF11&" "&$AF$7&" / ",""))-2))) | AH11: =IF(ISBLANK($A11),"",IF(ISBLANK(VLOOKUP($A11,Tableau6[],28,FALSE)),"",VLOOKUP($A11,Tableau6[],28,FALSE))) | AI11: =IF(ISBLANK($A11),"",IF(ISBLANK(VLOOKUP($A11,Tableau6[],29,FALSE)),"",VLOOKUP($A11,Tableau6[],29,FALSE))) | AJ11: =IF(ISBLANK($A11),"",IF(ISBLANK(VLOOKUP($A11,Tableau6[],30,FALSE)),"",VLOOKUP($A11,Tableau6[],30,FALSE))) | AK11: =IF(AND(OR(AI11="",AI11=0),OR(AJ11="",AJ11=0)),"",TRIM(LEFT(IF(AND(AI11<>"",AI11>0),AI11&" "&$AI$7&" / ","")&IF(AND(AJ11<>"",AJ11>0),AJ11&" "&$AJ$7&" / ",""),LEN(IF(AND(AI11<>"",AI11>0),AI11&" "&$AI$7&" / ","")&IF(AND(AJ11<>"",AJ11>0),AJ11&" "&$AJ$7&" / ",""))-2))) | AL11: =IF(ISBLANK($A11),"",IF(ISBLANK(VLOOKUP($A11,Tableau6[],31,FALSE)),"",VLOOKUP($A11,Tableau6[],31,FALSE))) | AM11: =IF(ISBLANK($A11),"",IF(ISBLANK(VLOOKUP($A11,Tableau6[],32,FALSE)),"",VLOOKUP($A11,Tableau6[],32,FALSE))) | AN11: =IF(ISBLANK($A11),"",IF(ISBLANK(VLOOKUP($A11,Tableau6[],33,FALSE)),"",VLOOKUP($A11,Tableau6[],33,FALSE))) | AO11: =IF(ISBLANK($A11),"",IF(ISBLANK(VLOOKUP($A11,Tableau6[],34,FALSE)),"",VLOOKUP($A11,Tableau6[],34,FALSE))) -> 1 | AP11: =IF(ISBLANK($A11),"",IF(ISBLANK(VLOOKUP($A11,Tableau6[],35,FALSE)),"",VLOOKUP($A11,Tableau6[],35,FALSE))) | AQ11: =IF(ISBLANK($A11),"",IF(ISBLANK(VLOOKUP($A11,Tableau6[],36,FALSE)),"",VLOOKUP($A11,Tableau6[],36,FALSE))) | AR11: =IF(ISBLANK($A11),"",IF(ISBLANK(VLOOKUP($A11,Tableau6[],37,FALSE)),"",VLOOKUP($A11,Tableau6[],37,FALSE))) | AS11: =IF(ISBLANK($A11),"",IF(ISBLANK(VLOOKUP($A11,Tableau6[],38,FALSE)),"",VLOOKUP($A11,Tableau6[],38,FALSE))) | AT11: =IF(ISBLANK($A11),"",IF(ISBLANK(VLOOKUP($A11,Tableau6[],39,FALSE)),"",VLOOKUP($A11,Tableau6[],39,FALSE))) | AU11: =IF(ISBLANK($A11),"",IF(ISBLANK(VLOOKUP($A11,Tableau6[],40,FALSE)),"",VLOOKUP($A11,Tableau6[],40,FALSE))) | AV11: =IF(ISBLANK($A11),"",IF(ISBLANK(VLOOKUP($A11,Tableau6[],41,FALSE)),"",VLOOKUP($A11,Tableau6[],41,FALSE))) | AW11: =IF(ISBLANK($A11),"",IF(ISBLANK(VLOOKUP($A11,Tableau6[],42,FALSE)),"",VLOOKUP($A11,Tableau6[],42,FALSE))) | AX11: =IF(ISBLANK($A11),"",IF(ISBLANK(VLOOKUP($A11,Tableau6[],43,FALSE)),"",VLOOKUP($A11,Tableau6[],43,FALSE))) | AY11: =IF(ISBLANK($A11),"",IF(ISBLANK(VLOOKUP($A11,Tableau6[],44,FALSE)),"",VLOOKUP($A11,Tableau6[],44,FALSE))) | AZ11: =IF(ISBLANK($A11),"",IF(ISBLANK(VLOOKUP($A11,Tableau6[],45,FALSE)),"",VLOOKUP($A11,Tableau6[],45,FALSE))) | BA11: =IF(ISBLANK($A11),"",IF(ISBLANK(VLOOKUP($A11,Tableau6[],46,FALSE)),"",VLOOKUP($A11,Tableau6[],46,FALSE))) | BB11: =IF(AND(OR(AK11="",AK11=0),OR(AL11="",AL11=0),OR(AM11="",AM11=0),OR(AN11="",AN11=0),OR(AO11="",AO11=0),OR(AP11="",AP11=0),OR(AQ11="",AQ11=0),OR(AR11="",AR11=0),OR(AS11="",AS11=0),OR(AT11="",AT11=0),OR(AU11="",AU11=0),OR(AV11="",AV11=0),OR(AW11="",AW11=0),OR(AX11="",AX11=0),OR(AY11="",AY11=0),OR(AZ11="",AZ11=0),OR(BA11="",BA11=0)),"",TRIM(LEFT(IF(AND(AK11<>"",AK11>0),AK11&" "&$AK$7&" / ","")&IF(AND(AL11<>"",AL11>0),AL11&" "&$AL$7&" / ","")&IF(AND(AM11<>"",AM11>0),AM11&" "&$AM$7&" / ","")&IF(AND(AN11<>"",AN11>0),AN11&" "&$AN$7&" / ","")&IF(AND(AO11<>"",AO11>0),AO11&" "&$AO$7&" / ","")&IF(AND(AP11<>"",AP11>0),AP11&" "&$AP$7&" / ","")&IF(AND(AQ11<>"",AQ11>0),AQ11&" "&$AQ$7&" / ","")&IF(AND(AR11<>"",AR11>0),AR11&" "&$AR$7&" / ","")&IF(AND(AS11<>"",AS11>0),AS11&" "&$AS$7&" / ","")&IF(AND(AT11<>"",AT11>0),AT11&" "&$AT$7&" / ","")&IF(AND(AU11<>"",AU11>0),AU11&" "&$AU$7&" / ","")&IF(AND(AV11<>"",AV11>0),AV11&" "&$AV$7&" / ","")&IF(AND(AW11<>"",AW11>0),AW11&" "&$AW$7&" / ","")&IF(AND(AX11<>"",AX11>0),AX11&" "&$AX$7&" / ","")&IF(AND(AY11<>"",AY11>0),AY11&" "&$AY$7&" / ","")&IF(AND(AZ11<>"",AZ11>0),AZ11&" "&$AZ$7&" / ","")&IF(AND(BA11<>"",BA11>0),BA11&" "&" / ",""),LEN(IF(AND(AK11<>"",AK11>0),AK11&" "&$AK$7&" / ","")&IF(AND(AL11<>"",AL11>0),AL11&" "&$AL$7&" / ","")&IF(AND(AM11<>"",AM11>0),AM11&" "&$AM$7&" / ","")&IF(AND(AN11<>"",AN11>0),AN11&" "&$AN$7&" / ","")&IF(AND(AO11<>"",AO11>0),AO11&" "&$AO$7&" / ","")&IF(AND(AP11<>"",AP11>0),AP11&" "&$AP$7&" / ","")&IF(AND(AQ11<>"",AQ11>0),AQ11&" "&$AQ$7&" / ","")&IF(AND(AR11<>"",AR11>0),AR11&" "&$AR$7&" / ","")&IF(AND(AS11<>"",AS11>0),AS11&" "&$AS$7&" / ","")&IF(AND(AT11<>"",AT11>0),AT11&" "&$AT$7&" / ","")&IF(AND(AU11<>"",AU11>0),AU11&" "&$AU$7&" / ","")&IF(AND(AV11<>"",AV11>0),AV11&" "&$AV$7&" / ","")&IF(AND(AW11<>"",AW11>0),AW11&" "&$AW$7&" / ","")&IF(AND(AX11<>"",AX11>0),AX11&" "&$AX$7&" / ","")&IF(AND(AY11<>"",AY11>0),AY11&" "&$AY$7&" / ","")&IF(AND(AZ11<>"",AZ11>0),AZ11&" "&$AZ$7&" / ","")&IF(AND(BA11<>"",BA11>0),BA11&" "" / ",""))-2))) -> 1 هاتف جوال
A12: المجموع | B12: *** | C12: =SUM(C8:C11) -> 3 | D12: =SUM(D8:D11) -> 1 | E12: =SUM(E8:E11) -> 2 | F12: =SUM(F8:F11) -> 0 | G12: =SUM(G8:G11) -> 0 | H12: =SUM(H8:H11) -> 2 | I12: =SUM(I8:I11) -> 2 | J12: =SUM(J8:J11) -> 0 | ... P12: =SUM(P8:P11) -> 0 | Q12: **** | R12: =IF(AND(OR(L12="",L12=0),OR(M12="",M12=0),OR(N12="",N12=0),OR(O12="",O12=0)*OR(P12="",P12=0)),"",TRIM(LEFT(IF(AND(L12<>"",L12>0),L12&" "&$L$7&" / ","")&IF(AND(M12<>"",M12>0),M12&" "&$M$7&" / ","")&IF(AND(N12<>"",N12>0),N12&" "&$N$7&" / ","")&IF(AND(O12<>"",O12>0),O12&" "&$O$7&" / ","")&IF(AND(P12<>"",P12>0),P12&" "&$P$7&" / ",""),LEN(IF(AND(L12<>"",L12>0),L12&" "&$L$7&" / ","")&IF(AND(M12<>"",M12>0),M12&" "&$M$7&" / ","")&IF(AND(N12<>"",N12>0),N12&" "&$N$7&" / ","")&IF(AND(O12<>"",O12>0),O12&" "&$O$7&" / ","")&IF(AND(P12<>"",P12>0),P12&" "&$P$7&" / ",""))-2))) -> 1 قطع | S12: =SUM(S8:S11) -> 22 | T12: =SUM(T8:T11) -> 0 | U12: =IF(AND(OR(S12="",S12=0),OR(T12="",T12=0)),"",TRIM(LEFT(IF(AND(S12<>"",S12>0),S12&" "&$S$7&" / ","")&IF(AND(T12<>"",T12>0),T12&" "&$T$7&" / ",""),LEN(IF(AND(S12<>"",S12>0),S12&" "&$S$7&" / ","")&IF(AND(T12<>"",T12>0),T12&" "&$T$7&" / ",""))-2))) -> 22 قرص | V12: =SUM(V8:V11) -> 0 | W12: =SUM(W8:W11) -> 0 | X12: =SUM(X8:X11) -> 0 | Y12: 0 | Z12: =SUM(Z8:Z11) -> 0 | AA12: =SUM(AA8:AA11) -> 0 | AB12: =SUM(AB8:AB11) -> 0 | AC12: 0 | AD12: =SUM(AD8:AD11) -> 0 | AE12: =SUM(AE8:AE11) -> 0 | AF12: =SUM(AF8:AF11) -> 0 | AG12: 0 | AH12: 0 | AI12: =SUM(AI8:AI11) -> 0 | AJ12: =SUM(AJ8:AJ11) -> 0 | AK12: =IF(AND(OR(AI12="",AI12=0),OR(AJ12="",AJ12=0)),"",TRIM(LEFT(IF(AND(AI12<>"",AI12>0),AI12&" "&$AI$7&" / ","")&IF(AND(AJ12<>"",AJ12>0),AJ12&" "&$AJ$7&" / ",""),LEN(IF(AND(AI12<>"",AI12>0),AI12&" "&$AI$7&" / ","")&IF(AND(AJ12<>"",AJ12>0),AJ12&" "&$AJ$7&" / ",""))-2))) | AL12: =SUM(AL8:AL11) -> 0 | AM12: =SUM(AM8:AM11) -> 0 | AN12: =SUM(AN8:AN11) -> 0 | AO12: =SUM(AO8:AO11) -> 1 | AP12: =SUM(AP8:AP11) -> 0 | AQ12: =SUM(AQ8:AQ11) -> 0 | AR12: =SUM(AR8:AR11) -> 1 | AS12: =SUM(AS8:AS11) -> 1 | ... BA12: =SUM(BA8:BA11) -> 0 | BB12: ******

Sheet غرق مراكب الهجرة
B2: الإدارة العامة للحرس الوطني إدارة عمليات الحرس الوطني عـــــــــــ/ 3932 /ــــدد
D5: كشف يومي في حالات غرق مراكب الهجرة غير النظامية و عمليات الإنقاذ ليوم 2026/01/11
C10: الإقليم البحري | D10: عدد المراكب التي تعرضت للغرق | E10: عدد المراكب التي تم التدخل لإنقاذها | F10: عدد المجتازين الذين تم إنقاذهم | J10: عدد الجثث تم انتشالها
F11: تونسيين | H11: أجانب | J11: تونسيين | L11: أجانب | N11: جثث مجهولة الهوية
F12: ذكور | G12: إناث | H12: ذكور | I12: إناث | J12: ذكور | K12: إناث | L12: ذكور | M12: إناث
C13: إقليم الحرس البحري بالشمال | D13: 0 | E13: 0 | F13: 0 | G13: 0 | H13: 0 | I13: 0 | J13: 0 | K13: 0 | L13: 0 | M13: 0 | N13: 0
C14: إقليم الحرس البحري بالساحل | D14: 0 | E14: 0 | F14: 0 | G14: 0 | H14: 0 | I14: 0 | J14: 0 | K14: 0 | L14: 0 | M14: 0 | N14: 0
C15: إقليم الحرس البحري بالوسط | D15: 0 | E15: 0 | F15: 0 | G15: 0 | H15: 0 | I15: 0 | J15: 0 | K15: 0 | L15: 0 | M15: 0 | N15: 0
C16: إقليم الحرس البحري بالجنوب | D16: 0 | E16: 0 | F16: 0 | G16: 0 | H16: 0 | I16: 0 | J16: 0 | K16: 0 | L16: 0 | M16: 0 | N16: 0
C17: المجموع | D17: =D16+D15+D14+D13 -> 0 | E17: =E16+E15+E14+E13 -> 0 | F17: =F16+F15+F14+F13 -> 0 | G17: =G16+G15+G14+G13 -> 0 | H17: =H16+H15+H14+H13 -> 0 | I17: =I16+I15+I14+I13 -> 0 | J17: =J16+J15+J14+J13 -> 0 | K17: =K16+K15+K14+K13 -> 0 | ... M17: =M16+M15+M14+M13 -> 0 | N17: =SUM(N13:N16) -> 0
C18: المجموع العـــــــــام | F18: =F17+G17 -> 0 | H18: =H17+I17 -> 0 | J18: =J17+K17 -> 0 | L18: =L17+M17 -> 0 | N18: 0
F19: =H18+F18 -> 0 | J19: =J18+L18 -> 0

Sheet بطاقة الاجتياز
B3: بطاقــة الموضــوع:بشـــــأن التصـــدي لظــــاهـرة الهـجــــرة غـيــر النظامية ليوم 11 جانفي 2026. -// - أتشرف بموافاتكم بأهم ما تم تسجيله بخصوص التصدي لظاهرة الهجرة غير النظامية بمرجع نظر الحرس الوطني
B4: • الحـــدود البحرية:
B6: الأقاليم | C6: عدد العمليات | D6: مكان انطلاق العملية | E6: عدد محاولي الاجتياز | Q6: عدد المنظمين | R6: عدد الوسطاء | S6: عدد المنظمين و الوسطاء مفتش عنهم | T6: عدد المفتش عنهم في قضايا حق عام | U6: عدد العناصر السلفية | V6: عدد الاطراف الامنية المورطة | W6: المحجوز
E7: تونسيين ذكور | F7: تونسيين اناث | G7: تونسيين | H7: افارقة ذكور | I7: افارقة اناث | J7: أفارقة | K7: جنسيات أخرى ذكور | L7: جنسيات أخرى اناث | M7: جنسيات مختلفة | N7: الموقوفين تونسيين | O7: الموقوفين أجانب | P7: عدد الإيقافات
C8: =IF(ISBLANK($B8),"",IF(ISBLANK(VLOOKUP($B8,الاجتياز!$B$9:$AN$38,2,FALSE)),"",VLOOKUP($B8,الاجتياز!$B$9:$AN$38,2,FALSE))) | D8: =IF(ISBLANK($B8),"",IF(ISBLANK(VLOOKUP($B8,الاجتياز!$B$9:$AN$38,3,FALSE)),"",VLOOKUP($B8,الاجتياز!$B$9:$AN$38,3,FALSE))) | E8: =IF(ISBLANK($B8),"",IF(ISBLANK(VLOOKUP($B8,الاجتياز!$B$9:$AN$38,4,FALSE)),"",VLOOKUP($B8,الاجتياز!$B$9:$AN$38,4,FALSE))) | F8: =IF(ISBLANK($B8),"",IF(ISBLANK(VLOOKUP($B8,الاجتياز!$B$9:$AN$38,5,FALSE)),"",VLOOKUP($B8,الاجتياز!$B$9:$AN$38,5,FALSE))) | G8: =IF(SUM(E8,F8)=0,"",SUM(E8,F8)) | H8: =IF(ISBLANK($B8),"",IF(ISBLANK(VLOOKUP($B8,الاجتياز!$B$9:$AN$38,6,FALSE)),"",VLOOKUP($B8,الاجتياز!$B$9:$AN$38,6,FALSE))) | I8: =IF(ISBLANK($B8),"",IF(ISBLANK(VLOOKUP($B8,الاجتياز!$B$9:$AN$38,7,FALSE)),"",VLOOKUP($B8,الاجتياز!$B$9:$AN$38,7,FALSE))) | J8: =IF(SUM(H8,I8)=0,"",SUM(H8,I8)) | K8: =IF(ISBLANK($B8),"",IF(ISBLANK(VLOOKUP($B8,الاجتياز!$B$9:$AN$38,8,FALSE)),"",VLOOKUP($B8,الاجتياز!$B$9:$AN$38,8,FALSE))) | L8: =IF(ISBLANK($B8),"",IF(ISBLANK(VLOOKUP($B8,الاجتياز!$B$9:$AN$38,9,FALSE)),"",VLOOKUP($B8,الاجتياز!$B$9:$AN$38,9,FALSE))) | M8: =IF(SUM(K8,L8)=0,"",SUM(K8,L8)) | N8: =IF(ISBLANK($B8),"",IF(ISBLANK(VLOOKUP($B8,الاجتياز!$B$9:$AN$38,13,FALSE)),"",VLOOKUP($B8,الاجتياز!$B$9:$AN$38,13,FALSE))) | O8: =IF(ISBLANK($B8),"",IF(ISBLANK(VLOOKUP($B8,الاجتياز!$B$9:$AN$38,14,FALSE)),"",VLOOKUP($B8,الاجتياز!$B$9:$AN$38,14,FALSE))) | P8: =IF(SUM(N8,O8)=0,"",SUM(N8,O8)) | Q8: =IF(ISBLANK($B8),"",IF(ISBLANK(VLOOKUP($B8,الاجتياز!$B$9:$AN$38,15,FALSE)),"",VLOOKUP($B8,الاجتياز!$B$9:$AN$38,15,FALSE))) | R8: =IF(ISBLANK($B8),"",IF(ISBLANK(VLOOKUP($B8,الاجتياز!$B$9:$AN$38,16,FALSE)),"",VLOOKUP($B8,الاجتياز!$B$9:$AN$38,16,FALSE))) | S8: =IF(ISBLANK($B8),"",IF(ISBLANK(VLOOKUP($B8,الاجتياز!$B$9:$AN$38,20,FALSE)),"",VLOOKUP($B8,الاجتياز!$B$9:$AN$38,20,FALSE))) | T8: =IF(ISBLANK($B8),"",IF(ISBLANK(VLOOKUP($B8,الاجتياز!$B$9:$AN$38,21,FALSE)),"",VLOOKUP($B8,الاجتياز!$B$9:$AN$38,21,FALSE))) | U8: =IF(ISBLANK($B8),"",IF(ISBLANK(VLOOKUP($B8,الاجتياز!$B$9:$AN$38,22,FALSE)),"",VLOOKUP($B8,الاجتياز!$B$9:$AN$38,22,FALSE))) | V8: =IF(ISBLANK($B8),"",IF(ISBLANK(VLOOKUP($B8,الاجتياز!$B$9:$AN$38,18,FALSE)),"",VLOOKUP($B8,الاجتياز!$B$9:$AN$38,18,FALSE))) | W8: =IF(ISBLANK($B8),"",IF(ISBLANK(VLOOKUP($B8,الاجتياز!$B$9:$AN$38,39,FALSE)),"",VLOOKUP($B8,الاجتياز!$B$9:$AN$38,39,FALSE)))
C9: =IF(ISBLANK($B9),"",IF(ISBLANK(VLOOKUP($B9,الاجتياز!$B$9:$AN$38,2,FALSE)),"",VLOOKUP($B9,الاجتياز!$B$9:$AN$38,2,FALSE))) | D9: =IF(ISBLANK($B9),"",IF(ISBLANK(VLOOKUP($B9,الاجتياز!$B$9:$AN$38,3,FALSE)),"",VLOOKUP($B9,الاجتياز!$B$9:$AN$38,3,FALSE))) | E9: =IF(ISBLANK($B9),"",IF(ISBLANK(VLOOKUP($B9,الاجتياز!$B$9:$AN$38,4,FALSE)),"",VLOOKUP($B9,الاجتياز!$B$9:$AN$38,4,FALSE))) | F9: =IF(ISBLANK($B9),"",IF(ISBLANK(VLOOKUP($B9,الاجتياز!$B$9:$AN$38,5,FALSE)),"",VLOOKUP($B9,الاجتياز!$B$9:$AN$38,5,FALSE))) | G9: =IF(SUM(E9,F9)=0,"",SUM(E9,F9)) | H9: =IF(ISBLANK($B9),"",IF(ISBLANK(VLOOKUP($B9,الاجتياز!$B$9:$AN$38,6,FALSE)),"",VLOOKUP($B9,الاجتياز!$B$9:$AN$38,6,FALSE))) | I9: =IF(ISBLANK($B9),"",IF(ISBLANK(VLOOKUP($B9,الاجتياز!$B$9:$AN$38,7,FALSE)),"",VLOOKUP($B9,الاجتياز!$B$9:$AN$38,7,FALSE))) | J9: =IF(SUM(H9,I9)=0,"",SUM(H9,I9)) | K9: =IF(ISBLANK($B9),"",IF(ISBLANK(VLOOKUP($B9,الاجتياز!$B$9:$AN$38,8,FALSE)),"",VLOOKUP($B9,الاجتياز!$B$9:$AN$38,8,FALSE))) | L9: =IF(ISBLANK($B9),"",IF(ISBLANK(VLOOKUP($B9,الاجتياز!$B$9:$AN$38,9,FALSE)),"",VLOOKUP($B9,الاجتياز!$B$9:$AN$38,9,FALSE))) | M9: =IF(SUM(K9,L9)=0,"",SUM(K9,L9)) | N9: =IF(ISBLANK($B9),"",IF(ISBLANK(VLOOKUP($B9,الاجتياز!$B$9:$AN$38,13,FALSE)),"",VLOOKUP($B9,الاجتياز!$B$9:$AN$38,13,FALSE))) | O9: =IF(ISBLANK($B9),"",IF(ISBLANK(VLOOKUP($B9,الاجتياز!$B$9:$AN$38,14,FALSE)),"",VLOOKUP($B9,الاجتياز!$B$9:$AN$38,14,FALSE))) | P9: =IF(SUM(N9,O9)=0,"",SUM(N9,O9)) | Q9: =IF(ISBLANK($B9),"",IF(ISBLANK(VLOOKUP($B9,الاجتياز!$B$9:$AN$38,15,FALSE)),"",VLOOKUP($B9,الاجتياز!$B$9:$AN$38,15,FALSE))) | R9: =IF(ISBLANK($B9),"",IF(ISBLANK(VLOOKUP($B9,الاجتياز!$B$9:$AN$38,16,FALSE)),"",VLOOKUP($B9,الاجتياز!$B$9:$AN$38,16,FALSE))) | S9: =IF(ISBLANK($B9),"",IF(ISBLANK(VLOOKUP($B9,الاجتياز!$B$9:$AN$38,20,FALSE)),"",VLOOKUP($B9,الاجتياز!$B$9:$AN$38,20,FALSE))) | T9: =IF(ISBLANK($B9),"",IF(ISBLANK(VLOOKUP($B9,الاجتياز!$B$9:$AN$38,21,FALSE)),"",VLOOKUP($B9,الاجتياز!$B$9:$AN$38,21,FALSE))) | U9: =IF(ISBLANK($B9),"",IF(ISBLANK(VLOOKUP($B9,الاجتياز!$B$9:$AN$38,22,FALSE)),"",VLOOKUP($B9,الاجتياز!$B$9:$AN$38,22,FALSE))) | V9: =IF(ISBLANK($B9),"",IF(ISBLANK(VLOOKUP($B9,الاجتياز!$B$9:$AN$38,18,FALSE)),"",VLOOKUP($B9,الاجتياز!$B$9:$AN$38,18,FALSE))) | W9: =IF(ISBLANK($B9),"",IF(ISBLANK(VLOOKUP($B9,الاجتياز!$B$9:$AN$38,39,FALSE)),"",VLOOKUP($B9,الاجتياز!$B$9:$AN$38,39,FALSE)))
B10: المجموع | C10: =SUM(C8:C9) -> 0 | D10: *** | E10: =SUM(#REF!) -> #REF! | F10: =SUM(#REF!) -> #REF! | G10: =SUM(G8:G9) -> 0 | H10: =SUM(H8:H9) -> 0 | I10: =SUM(I8:I9) -> 0 | J10: =SUM(J8:J9) -> 0 | K10: =SUM(K8:K9) -> 0 | L10: =SUM(L8:L9) -> 0 | M10: =SUM(M8:M9) -> 0 | N10: =SUM(#REF!) -> #REF! | O10: =SUM(#REF!) -> #REF! | P10: =SUM(P8:P9) -> 0 | Q10: =SUM(Q8:Q9) -> 0 | R10: =SUM(R8:R9) -> 0 | S10: =SUM(S8:S9) -> 0 | T10: =SUM(T8:T9) -> 0 | U10: =SUM(U8:U9) -> 0 | V10: =SUM(V8:V9) -> 0 | W10: *******
E11: =+G10+J10+M10 -> 0 | Q11: =Q10+R10 -> 0
B14: • الحـــدود البرية:
B16: الأقاليم | C16: عدد العمليات | D16: مكان انطلاق العملية | E16: عدد محاولي الاجتياز | Q16: عدد المنظمين | R16: عدد الوسطاء | S16: عدد المنظمين و الوسطاء مفتش عنهم | T16: عدد المفتش عنهم في قضايا حق عام | U16: عدد العناصر السلفية | V16: عدد الاطراف الامنية المورطة | W16: المحجوز
E17: تونسيين ذكور | F17: تونسيين اناث | G17: تونسيين | H17: افارقة ذكور | I17: افارقة اناث | J17: أفارقة | K17: جنسيات أخرى ذكور | L17: جنسيات أخرى اناث | M17: جنسيات مختلفة | N17: الموقوفين تونسيين | O17: الموقوفين أجانب | P17: عدد الإيقافات
